File: .csv
Time Stamp (sec),Temperature (K),Magnetic Field (Oe),AC Frequency (Hz),AC Amplitude (Oe),M-Std.Dev. (emu),Mp (emu),Mpp (emu),Xp (emu/Oe),Xpp (emu/Oe),Moment (emu),Phase (deg),Calcoil' (emu),Calcoil'' (emu),Calcoil (emu),CC Phase (deg),Count,Gain,Measure Type,Elapsed (sec),Sample Center (cm),Max.Signal (V),PPMS Status (code),DSP Status (code),Min.Temperature (K),Max.Temperature (K),Min.Field (Oe),Max.Field (Oe),PPMS Temperature (K),Map 25 ()
11416265.29,2.2093533875,148.881875,10.0,3.00137149090889,1.93278050783493e-06,0.0001882217379126,3.01134761413899e-06,1.2642354075175368e-06,2.022642188069562e-08,0.0001882458255508,0.916593332243564,1.53917895911603e-08,1.02057473563187e-10,1.53921279408164e-08,0.379902335277718,320,25,5,13.4965986394558,-0.076805167652275,0.0001079771024983,4449,0,2.2042522,2.2246571,-3.666,707.616,2.206275,2.2093533875
11416577.81,2.1992924875,1000.044,79.4333643988816,3.00128073596109,7.22055490327542e-08,6.16726536419608e-06,1.32839338759541e-06,6.166994016459356e-09,1.3283349408580123e-09,6.30870755897116e-06,12.1554682683693,1.53981997020503e-08,7.1241779940632e-11,1.53983645058633e-08,0.265084507927232,316,25,5,13.4965986394558,-0.076805167652275,0.0001420036799249,4373,0,2.1977971,2.2007561,1000.044,1000.044,2.1961,2.1992924875
11416889.99,2.1987715625,1000.044,630.960391425909,2.99998845647009,2.23754816282688e-08,4.74769078346415e-06,1.05629222139016e-06,4.7474818942608025e-09,1.0562457465773107e-09,4.86377641677326e-06,12.5431801758476,1.53963753140789e-08,-1.18816398874372e-10,1.5396833770247e-08,-0.442152319322076,210,25,5,13.4965986394558,-0.076805167652275,0.0004247250068444,4369,0,2.1980376,2.1992817,1000.044,1000.044,2.19635,2.1987715625
11417202.38,2.2121495375,1000.044,5011.89934762349,2.99865903132609,1.07939798937819e-08,3.26716033888793e-06,9.79403231349317e-07,3.267016590157963e-09,9.79360139503179e-10,3.4108015728828e-06,16.6872593564739,1.53317721191583e-08,-1.5976010133879102e-09,1.54147839852454e-08,-5.94886463919482,455,25,5,13.4965986394558,-0.076805167652275,0.0025551032576019,4369,0,2.210129,2.2131126,1000.044,1000.044,2.1948875,2.2121495375
11418175.95,2.998168825,1000.044,31.6230195712954,3.00129825981149,1.57507708380661e-07,5.75356545651398e-06,2.90935578386258e-06,5.753312310772306e-09,2.909227777840355e-09,6.44731467662977e-06,26.8239611248479,1.53968003981531e-08,4.501334241335e-11,1.539686619743e-08,0.16750669798206,496,25,5,13.4965986394558,-0.076805167652275,0.0001181341548015,4373,0,2.9577255,3.0264719,1000.044,1000.044,2.995875,2.998168825
11418486.62,2.9951987875,1000.044,251.189655172414,3.00109333704547,2.65423165290434e-08,4.25006335447976e-06,1.07811993022992e-06,4.249876359919924e-09,1.0780724950401383e-09,4.38467571218793e-06,14.2340588405435,1.53814155971626e-08,-3.9544655118799194e-11,1.53814664304931e-08,-0.147303532262242,502,25,5,13.4965986394558,-0.076805167652275,0.0002313928692955,4373,0,2.9569848,3.0085225,1000.044,1000.044,3.0050625,2.9951987875
11418799.73,3.004015075,1000.044,1995.30009319664,3.00069531719102,1.1025326908371e-08,3.19256920172828e-06,7.87096860674918e-07,3.192428734863946e-09,7.870622299368008e-10,3.28816355674536e-06,13.8495244599196,1.53814706015715e-08,-6.25516596168691e-10,1.53941842550715e-08,-2.32875805128629,399,25,5,13.4965986394558,-0.076805167652275,0.0011104389762989,4373,0,2.9983912,3.0114081,1000.044,1000.044,3.0042875,3.004015075
11419339.96,3.990811575,1000.044,12.5890027958993,3.00130103721641,4.62110325590774e-07,8.4552033084571e-06,2.2965903895379e-05,8.45483129588008e-09,2.296489344006764e-08,2.44729075656965e-05,69.7881440680363,1.53858012213125e-08,2.9200648365444794e-11,1.53858289311823e-08,0.108741291890828,384,25,5,13.4965986394558,-0.076805167652275,0.000106483678585,4373,0,3.964282,4.0107894,1000.044,1000.044,3.9921375,3.990811575
11419653.63,4.001818125,1000.044,100.0,3.00126855660348,1.08467549929532e-07,4.2833685945336e-06,3.87519085566457e-06,4.283180134607677e-09,3.875020354768961e-09,5.77618824870373e-06,42.1358450962214,1.53913780981866e-08,8.274562067942269e-11,1.53916005210336e-08,0.308024995121848,400,25,5,13.4965986394558,-0.076805167652275,0.0001518425790106,4369,0,3.9982722,4.0043559,1000.044,1000.044,4.007125,4.001818125
11419968.22,4.001190525,1000.044,794.330848089469,2.99922120559246,1.20583795254033e-08,3.01752729711311e-06,9.73499743957822e-07,3.017394531753713e-09,9.734569118537005e-10,3.17067386217957e-06,17.8804824529122,1.5404512385746e-08,-1.53565595431202e-10,1.54052778045286e-08,-0.571155310088045,264,25,5,13.4965986394558,-0.076805167652275,0.0005071086405157,4373,0,3.9957922,4.0090442,1000.044,1000.044,4.007225,4.001190525
11420281.89,4.0074871,1000.044,6309.59972041006,3.00156376687455,4.128005168263751e-09,2.21832350208959e-06,5.67002886769041e-07,2.2182259001499836e-09,5.669779397396925e-10,2.28964002269516e-06,14.3378112059266,1.53010146023904e-08,-2.0161887202520303e-09,1.5433277837784e-08,-7.50652199004543,573,25,5,13.4965986394558,-0.076805167652275,0.0031671946684278,4369,0,3.998049,4.0187492,1000.044,1000.044,4.006375,4.0074871
11420821.24,4.9983141875,1000.044,39.8108108108108,3.00129632945247,2.61299961380561e-07,7.5071175330917e-06,2.03956708498003e-05,7.506787234453385e-09,2.039477347976719e-08,2.173338912984e-05,69.7926473163964,1.54023651790049e-08,4.8782674956036796e-11,1.54024424315366e-08,0.181467716806068,312,25,5,13.4965986394558,-0.076805167652275,0.0001218411886139,4369,0,4.9966969,5.0016408,1000.044,1000.044,5.0006125,4.9983141875
11421133.19,4.99936915,1000.044,316.22972972973,3.00097156658191,2.80250124352595e-08,3.04074419859233e-06,3.2571611522653e-06,3.040610411734214e-09,3.257017843480187e-09,4.45592011296199e-06,46.9680989337915,1.5386086548704e-08,-5.1058416372678095e-11,1.53861712666307e-08,-0.190134185129011,316,25,5,13.4965986394558,-0.076805167652275,0.0002653005379909,4369,0,4.998354,5.0002933,1000.044,1000.044,5.0023,4.99936915
11421451.34,5.0008594875,1000.044,2511.90074557316,3.00138250558532,1.41425157013408e-08,2.26290470908983e-06,8.00516927293322e-07,2.262805145663421e-09,8.004817060982537e-10,2.40032603479279e-06,19.4815569955491,1.5375410364898e-08,-7.93471603400366e-10,1.53958709099036e-08,-2.95421573603369,502,25,5,13.4965986394558,-0.076805167652275,0.0013580003406329,4369,0,4.9984212,5.0032291,1000.044,1000.044,5.000775,5.0008594875
11421963.93,5.502798325,1000.044,15.8490214352283,3.00130073123969,5.5655535273815e-07,4.32383732567742e-05,4.92741017493757e-05,4.323647085205671e-08,4.927193378428919e-08,6.55552745787855e-05,48.7328192530574,1.5371931527664e-08,3.6765112926952096e-11,1.53719754932383e-08,0.137034294208119,480,25,5,13.4965986394558,-0.076805167652275,0.0001091888104831,4369,0,5.4763575,5.515336,1000.044,1000.044,5.5066625,5.502798325
11422278.69,5.503962575,1000.044,125.890027958993,3.00124925555362,4.66458808307702e-08,4.25908107388726e-06,1.04961750175755e-05,4.2588936825652275e-09,1.0495713206194428e-08,1.13273766421675e-05,67.9139360413976,1.53803547360054e-08,-1.26545177513618e-11,1.53803599418928e-08,-0.04714132461595,500,25,5,13.4965986394558,-0.076805167652275,0.0001667072952656,4373,0,5.4734616,5.5371208,1000.044,1000.044,5.5129125,5.503962575
11422588.92,5.4995857625,1000.044,1000.0,2.99800636951636,1.02452329162175e-08,2.43446602032029e-06,1.76505918247978e-06,2.4343589085283147e-09,1.7649815232927552e-09,3.0070016165194e-06,35.9432120487101,1.54174908712836e-08,-1.99055241380114e-10,1.54187758189563e-08,-0.739704771897948,333,25,5,13.4965986394558,-0.076805167652275,0.0006080714361082,4373,0,5.4639015,5.5325818,1000.044,1000.044,5.504525,5.4995857625
11422937.82,5.5011675625,1000.044,7943.30009319665,2.99927656587788,1.02273963181554e-08,1.81678989352241e-06,5.34520931392378e-07,1.8167099582842457e-09,5.344974135061837e-10,1.89378936085873e-06,16.3945025590022,1.52553155264625e-08,-2.52899534123933e-09,1.54635205968091e-08,-9.41277306011091,611,5,5,13.4965986394558,-0.076805167652275,0.00390510407858,4373,0,5.473527,5.5261202,1000.044,1000.044,5.495975,5.5011675625
11425264.34,6.00428455,1000.044,50.118825722274,3.00129326999639,3.26443910727279e-07,1.59664546231086e-05,3.17917878012786e-05,1.596575213001488e-08,3.179038902416154e-08,3.55759110190212e-05,63.3333064390183,1.54112376329907e-08,5.2727077798797e-11,1.54113278313467e-08,0.196027555235976,400,25,5,13.4965986394558,-0.076805167652275,0.0001289705405403,4373,0,5.9800282,6.0298295,1000.044,1000.044,6.0071625,6.00428455
11425575.49,6.00174555,1000.044,398.109972041007,3.00077860318821,1.18711802599622e-08,2.90528211360436e-06,5.16730959093344e-06,2.90515428681574e-09,5.167082239314911e-09,5.92804795596173e-06,60.6534463669746,1.53865328057318e-08,-6.87564102111476e-11,1.53866864277468e-08,-0.256030773664691,398,25,5,13.4965986394558,-0.076805167652275,0.0003073491059303,4373,0,5.9796867,6.0415797,1000.044,1000.044,6.000725,6.00174555
11425887.57,5.9923329375,1000.044,3162.30009319665,3.00179839873488,8.62525679194896e-09,1.97752521663897e-06,1.00600314906649e-06,1.977438209357758e-09,1.0059588868754676e-09,2.21870419803422e-06,26.9632707484659,1.53656851132302e-08,-1.00304384185148e-09,1.53983887451779e-08,-3.73486473625832,451,25,5,13.4965986394558,-0.076805167652275,0.0016709319432592,4373,0,5.9615293,6.0184984,1000.044,1000.044,5.9886625,5.9923329375
11427094.86,6.49058205,1000.044,19.952935694315,3.00130024631558,4.63277761106374e-07,6.39009967690631e-05,3.90108805062166e-05,6.389818524891215e-08,3.9009164102996065e-08,7.48677913788708e-05,31.4036224043543,1.53680579592117e-08,1.8291011897972798e-11,1.53680688441589e-08,0.0681932156103184,304,25,5,13.4965986394558,-0.076805167652275,0.0001141135933673,4373,0,6.4615312,6.5245318,1000.044,1000.044,6.4851875,6.49058205
11427407.87,6.491550725,1000.044,158.490214352283,3.00121865985064,4.48981680212475e-08,6.0350349926434e-06,1.61977252938158e-05,6.034769462787038e-09,1.619701262526029e-08,1.7285483853695e-05,69.5653439428463,1.53833179803012e-08,-1.7579488803401597e-11,1.53833280248939e-08,-0.0654754765696452,316,25,5,13.4965986394558,-0.076805167652275,0.0001841761936469,4373,0,6.467844,6.5216126,1000.044,1000.044,6.4818,6.491550725
11427726.56,6.50046645,1000.044,1258.90027958993,3.00024530415142,4.60951133531376e-08,2.2225694610732e-06,2.64225805995604e-06,2.2224716723196178e-09,2.6421418057165884e-09,3.45272974104518e-06,49.9306979840303,1.53850659145138e-08,-3.87057723274422e-10,1.53899339464171e-08,-1.44114410171778,419,25,5,13.4965986394558,-0.076805167652275,0.000747133179948,4373,0,6.4790635,6.532774,1000.044,1000.044,6.5004625,6.50046645
11428065.37,6.5050938625,1000.044,10000.0,2.99869557976582,9.990570457020081e-09,1.63600435221598e-06,5.73746943644925e-07,1.6359323711916477e-09,5.737216998901298e-10,1.73369426249599e-06,19.3257753026656,1.51898331188361e-08,-3.2068476677116604e-09,1.55246546545164e-08,-11.9211181339392,588,5,5,13.4965986394558,-0.076805167652275,0.004779727579463,4373,0,6.4744229,6.5304828,1000.044,1000.044,6.5025625,6.5050938625
11430164.97,7.0076611625,1000.044,63.096458527493,3.00128842085064,1.52866281987204e-07,2.95105100079482e-05,3.76837437415095e-05,2.9509211602637685e-08,3.768208572973739e-08,4.78637100871314e-05,51.9351552373887,1.53949851841298e-08,5.933415250508259e-11,1.53950995242391e-08,0.220823836216124,504,25,5,13.4965986394558,-0.076805167652275,0.0001355536609935,4373,0,6.9816279,7.0239258,1000.044,1000.044,7.0099875,7.0076611625
11430474.93,7.003774225,1000.044,501.189655172414,3.00047285468784,2.23051283870177e-08,3.07035615534246e-06,7.48611667598979e-06,3.0702210656155728e-09,7.485787301348531e-09,8.09129345699325e-06,67.6995024053615,1.53902601822293e-08,-9.033214587219409e-11,1.53905252793169e-08,-0.336290044390523,501,25,5,13.4965986394558,-0.076805167652275,0.0003595093926673,4373,0,6.9846621,7.0208306,1000.044,1000.044,7.0084125,7.003774225
11430791.24,6.9885922625,1000.044,3981.09972041007,2.99944376723863,1.88211619128713e-08,1.834870323321e-06,1.28355176399517e-06,1.8347895925789267e-09,1.2834952902024012e-09,2.23925305275202e-06,34.9740463375137,1.53512682750995e-08,-1.26650227824877e-09,1.54034238296194e-08,-4.71630518330352,568,25,5,13.4965986394558,-0.076805167652275,0.0020607024770491,4373,0,6.9607038,7.0243235,1000.044,1000.044,6.9955,6.9885922625
11431759.29,7.5094989,1000.044,25.1190587138863,3.00129947782247,4.56575395182191e-07,6.69022362494687e-05,2.62402403343526e-05,6.689929268059074e-08,2.623908581457676e-08,7.18641734662293e-05,21.4159898605503,1.53607093587836e-08,3.9677180663881795e-11,1.53607606023819e-08,0.14799641644196,400,25,5,13.4965986394558,-0.076805167652275,0.0001157684425019,4373,0,7.4490366,7.5602784,1000.044,1000.044,7.4998875,7.5094989
11432069.75,7.4985434375,1000.044,199.530288909599,3.00117017116012,3.86959621561929e-08,9.42351708590672e-06,2.17388133085876e-05,9.423102469398067e-09,2.1737856842886512e-08,2.3693431122022e-05,66.5638415476208,1.53823312928812e-08,-2.72238626340945e-11,1.53823553834467e-08,-0.101402757014682,398,25,5,13.4965986394558,-0.076805167652275,0.0002053449084692,4373,0,7.4803491,7.5394101,1000.044,1000.044,7.4897375,7.4985434375
11432383.59,7.5062634875,1000.044,1584.90027958993,3.00135812293117,1.34011551575252e-08,2.1432075200136e-06,3.41952036294821e-06,2.1431132230317864e-09,3.4193699106721407e-09,4.03564839727897e-06,57.9222926587946,1.53829961396057e-08,-4.92898577194846e-10,1.53908907876875e-08,-1.83523086848578,528,25,5,13.4965986394558,-0.076805167652275,0.0009092565059371,4373,0,7.479001,7.5340343,1000.044,1000.044,7.4974125,7.5062634875
11433050.47,8.0042104625,1000.044,10.0,3.00130123023475,8.06418587538122e-07,7.09834649678362e-05,8.47508948438835e-06,7.098034183279556e-08,8.474716596858089e-09,7.14876173935627e-05,6.80861396885048,1.54226764421365e-08,1.04641294353766e-10,1.5423031428332e-08,0.388740083705909,320,25,5,13.4965986394558,-0.076805167652275,0.0001054614286807,4373,0,7.9739151,8.0427608,1000.044,1000.044,8.00965,8.0042104625
11433361.6,8.0001291125,1000.044,79.4333643988816,3.00128073596109,1.00982842898458e-07,4.12526464538044e-05,3.53419100426115e-05,4.125083141722204e-08,3.5340355066988555e-08,5.43215559874957e-05,40.5872791988453,1.53945599928856e-08,7.0124807187926e-11,1.53947197071962e-08,0.260990096739864,316,25,5,13.4965986394558,-0.076805167652275,0.000143678668701,4373,0,7.9866805,8.0302782,1000.044,1000.044,7.995875,8.0001291125
11433674.9,8.0025051375,1000.044,630.960391425909,2.99998845647009,7.75902918208333e-09,3.63183967743849e-06,1.00143951425158e-05,3.6316798835236148e-09,1.0013954528516545e-08,1.06526226589071e-05,70.0662204109469,1.53959641122291e-08,-1.18488128782197e-10,1.53964200508335e-08,-0.440942549864417,210,25,5,13.4965986394558,-0.076805167652275,0.0004251229080388,4369,0,7.9457269,8.0320654,1000.044,1000.044,8.0022875,8.0025051375
11433986.74,8.001306875,1000.044,5011.89934762349,2.99865903132609,1.01695017075158e-08,1.70926069211376e-06,1.5694343247426e-06,1.7091854879522901e-09,1.5693652726706026e-09,2.32049482078402e-06,42.5579890827177,1.53320715870265e-08,-1.5981775909959902e-09,1.54151416069418e-08,-5.9508807910151,455,25,5,13.4965986394558,-0.076805167652275,0.0025535240118032,4369,0,7.9572339,8.0379686,1000.044,1000.044,7.99195,8.001306875
11434522.57,8.4920571875,1000.044,31.6230195712954,3.00129825981149,5.92006468394392e-07,6.40051038128743e-05,1.66120893462122e-05,6.400228771221496e-08,1.6611358446440557e-08,6.61257501019335e-05,14.5496979100313,1.54069915203197e-08,3.59325811026383e-11,1.54070334217067e-08,0.133626445417471,496,25,5,13.4965986394558,-0.076805167652275,0.0001179066988169,4369,0,8.4530916,8.5071659,1000.044,1000.044,8.5064,8.4920571875
11434835.3,8.49937605,1000.044,251.189655172414,3.00109333704547,2.80062546847947e-08,1.48692734103577e-05,2.59212531016146e-05,1.4868619191113291e-08,2.5920112616659466e-08,2.98832169304098e-05,60.1600162318072,1.53803639902561e-08,-3.8585302723272396e-11,1.53804123903865e-08,-0.14373979449789,502,25,5,13.4965986394558,-0.076805167652275,0.0002327932772661,4369,0,8.4862556,8.5160275,1000.044,1000.044,8.50715,8.49937605
11435148.14,8.4901300875,1000.044,1995.30009319664,3.00069531719102,3.80633337935219e-08,2.11068061255227e-06,4.3966595458223e-06,2.1105877466914156e-09,4.396466101313842e-09,4.87704703791899e-06,64.355985969554,1.53809208505522e-08,-6.25372309155049e-10,1.53936290957009e-08,-2.32830459585398,399,25,5,13.4965986394558,-0.076805167652275,0.0011094440581537,4369,0,8.4571629,8.526598,1000.044,1000.044,8.50075,8.4901300875
11435659.98,8.9938231625,1000.044,12.5890027958993,3.00130103721641,9.3301102471214e-07,6.75174751156417e-05,5.465058105261e-06,6.75145044774447e-08,5.4648176532842555e-09,6.77382927603373e-05,4.62759605861106,1.53961841037645e-08,3.0935207189158e-11,1.53962151824419e-08,0.115122968984366,384,25,5,13.4965986394558,-0.076805167652275,0.0001064754412771,4369,0,8.9475746,9.0307188,1000.044,1000.044,8.9976625,8.9938231625
11435967.54,8.99629675,1000.044,100.0,3.00126855660348,1.42409821258187e-07,4.69666793139818e-05,2.87244883168379e-05,4.6964612871015474e-08,2.8723224494960123e-08,5.50542023359394e-05,31.4496604738457,1.53911793983163e-08,8.772343384257449e-11,1.53914293901509e-08,0.326558996475095,400,25,5,13.4965986394558,-0.076805167652275,0.0001538999290194,4369,0,8.9596176,9.0186577,1000.044,1000.044,8.9973,8.99629675
11436275.65,9.0076599125,1000.044,794.330848089469,2.99922120559246,1.46594533162628e-08,4.67767021123337e-06,1.26170196532258e-05,4.677464402799647e-09,1.2616464528786533e-08,1.34562172817975e-05,69.6580967617002,1.54037739602078e-08,-1.54060833376743e-10,1.54045443605956e-08,-0.573024588550254,264,25,5,13.4965986394558,-0.076805167652275,0.0005076398220643,4369,0,8.9959269,9.0277786,1000.044,1000.044,9.0169,9.0076599125
11436587.47,9.00634765,1000.044,6309.59972041006,3.00156376687455,1.25642634936959e-08,1.62675004610833e-06,1.90796497888884e-06,1.626678472255551e-09,1.9078810321234265e-09,2.50731850254006e-06,49.5487578956016,1.5301270759147e-08,-2.01559395880608e-09,1.5433454112787e-08,-7.50420866290995,573,25,5,13.4965986394558,-0.076805167652275,0.0031669660364138,4369,0,8.9963913,9.0255661,1000.044,1000.044,9.0073875,9.00634765
11437094.31,9.5023709625,1000.044,39.8108108108108,3.00129632945247,2.11969440114958e-07,6.05700663298743e-05,1.09201577514998e-05,6.056740136421428e-08,1.091967728569923e-08,6.15465903241033e-05,10.220049355988,1.53958463876963e-08,4.8807895298149895e-11,1.539592375287e-08,0.181638408747187,312,25,5,13.4965986394558,-0.076805167652275,0.0001218623099161,4369,0,9.4744587,9.5244904,1000.044,1000.044,9.4956125,9.5023709625
11437405.84,9.4976536,1000.044,316.22972972973,3.00097156658191,1.98673107308655e-08,2.06775616396505e-05,2.76530099308404e-05,2.0676651866968352e-08,2.7651793251937313e-08,3.45289807784229e-05,53.2126662406596,1.53863639530334e-08,-5.08807166426734e-11,1.53864480807798e-08,-0.189469045755345,316,25,5,13.4965986394558,-0.076805167652275,0.0002679089492971,4369,0,9.463232,9.5147753,1000.044,1000.044,9.4921375,9.4976536
11437716.56,9.5060800375,1000.044,2511.90074557316,3.00138250558532,1.14307153193063e-08,2.21610564486072e-06,5.35668151744804e-06,2.216008140502538e-09,5.356445833831352e-09,5.79699586928893e-06,67.5246956360963,1.53745933927741e-08,-7.93014021819755e-10,1.53950314462796e-08,-2.95267171784172,502,25,5,13.4965986394558,-0.076805167652275,0.0013581856964686,4369,0,9.490634,9.5137138,1000.044,1000.044,9.5056125,9.5060800375
11438220.48,10.005056125,1000.044,15.8490214352283,3.00130073123969,7.74498935268989e-07,5.93535960704794e-05,1.75546505925567e-06,5.93509846271558e-08,1.7553878221914937e-09,5.93795505546472e-05,1.69410840997448,1.53695454966961e-08,1.86926418229891e-11,1.53695568638094e-08,0.0696838404602033,480,25,5,13.4965986394558,-0.076805167652275,0.0001086923753967,4369,0,9.9976854,10.0143871,1000.044,1000.044,9.98435,10.005056125
11438527.6,10.0142731875,1000.044,125.890027958993,3.00124925555362,9.99306500189551e-08,4.9246106645371e-05,2.18631801720207e-05,4.924393991201487e-08,2.1862218234418384e-08,5.38811438906181e-05,23.9391886731307,1.53777395658741e-08,-1.1798183753094299e-11,1.53777440918033e-08,-0.0439587365516445,500,25,5,13.4965986394558,-0.076805167652275,0.0001694186216192,4369,0,9.9880409,10.034524,1000.044,1000.044,9.9949625,10.0142731875
11438837.33,10.005936725,1000.044,1000.0,2.99800636951636,6.0731515493919804e-09,6.06055819902052e-06,1.4764290055158e-05,6.060291546192487e-09,1.4763640454977982e-08,1.59597815309782e-05,67.6824572635235,1.54169284648054e-08,-1.98964689556494e-10,1.54182122905548e-08,-0.73939528065074,333,25,5,13.4965986394558,-0.076805167652275,0.0006099458812725,4369,0,9.9964867,10.0150509,1000.044,1000.044,9.9836,10.005936725
11439178.17,10.0008842875,1000.044,7943.30009319665,2.99927656587788,7.50954014082011e-09,1.59438484661971e-06,2.24103734304944e-06,1.5943146967730521e-09,2.240938741744803e-09,2.75032932793014e-06,54.570070887861,1.52547199986442e-08,-2.52843870301411e-09,1.54628420580415e-08,-9.41109916230334,611,5,5,13.4965986394558,-0.076805167652275,0.0039041873241874,4369,0,9.9838047,10.0251608,1000.044,1000.044,9.974125,10.0008842875
11439664.27,10.507435075,1000.044,50.118825722274,3.00129326999639,1.74883948229671e-07,5.5209465686028e-05,7.34917001655043e-06,5.520703657641864e-08,7.34884666729707e-09,5.56964577084473e-05,7.58231318883571,1.53852725918799e-08,5.2512283841610695e-11,1.53853622078392e-08,0.195558482003556,400,25,5,13.4965986394558,-0.076805167652275,0.0001273211020163,4369,0,10.4926815,10.5215292,1000.044,1000.044,10.4846625,10.507435075
11439991.75,10.4994603375,1000.044,398.109972041007,3.00077860318821,2.43335886728534e-08,2.57272120002862e-05,2.69941684626286e-05,2.572608005276388e-08,2.6992980771474653e-08,3.72904085294924e-05,46.3766196668933,1.53856156009828e-08,-6.91753124831826e-11,1.53857711098619e-08,-0.257605990420132,398,25,5,13.4965986394558,-0.076805167652275,0.0003111533347781,4369,0,10.4896164,10.5212107,1000.044,1000.044,10.476925,10.4994603375
11440316.66,10.492842775,1000.044,3162.30009319665,3.00179839873488,9.051580738037471e-09,2.36332807353366e-06,6.27163193875183e-06,2.3632240916736265e-09,6.27135599908787e-09,6.70214046095159e-06,69.3521736415593,1.53651490098635e-08,-1.0029394754256e-09,1.53978469821816e-08,-3.73460715480172,451,25,5,13.4965986394558,-0.076805167652275,0.0016712703486691,4369,0,10.4766817,10.5159721,1000.044,1000.044,10.46265,10.492842775
11440894.16,11.007939825,1000.044,19.952935694315,3.00130024631558,3.06481989589289e-07,5.50237814955267e-05,1.65038115873787e-06,5.502136055566226e-08,1.6503085451618829e-09,5.50485266654484e-05,1.71801230609763,1.53503428228283e-08,1.75387374973705e-11,1.53503528423834e-08,0.0654640232407374,304,25,5,13.4965986394558,-0.076805167652275,0.0001115201420219,4369,0,11.0075455,11.0084915,1000.044,1000.044,10.9798875,11.007939825
11441214.11,11.002921,1000.044,158.490214352283,3.00121865985064,6.17906338294758e-08,4.81731837522673e-05,1.65248236324485e-05,4.817106422544138e-08,1.6524096572199324e-08,5.09286307386449e-05,18.9334810641288,1.53820082236995e-08,-1.68447472455496e-11,1.53820174469888e-08,-0.0627442479741944,316,25,5,13.4965986394558,-0.076805167652275,0.0001868229762099,4369,0,11.0005445,11.0042334,1000.044,1000.044,10.97535,11.002921
11441537.36,11.0009476125,1000.044,1258.90027958993,3.00024530415142,2.85257704069382e-08,7.77759822997743e-06,1.66285697320761e-05,7.77725603071208e-09,1.6627838107199384e-08,1.83575697073841e-05,64.9333314375265,1.53845397164052e-08,-3.8767911951021603e-10,1.53894235559801e-08,-1.44350613738044,419,25,5,13.4965986394558,-0.076805167652275,0.0007517967150771,4369,0,11.0002575,11.001441,1000.044,1000.044,10.9739125,11.0009476125
11441888.75,11.0027224125,1000.044,10000.0,2.99869557976582,8.97030032071697e-09,1.57158245432584e-06,2.56983334474645e-06,1.5715133077402995e-09,2.56972027705426e-09,3.01229394822543e-06,58.5521149065434,1.51895537354665e-08,-3.2060668757795504e-09,1.55242200285423e-08,-11.9185115829226,588,5,5,13.4965986394558,-0.076805167652275,0.0047797836155708,4369,0,11.0023375,11.0033894,1000.044,1000.044,10.9702625,11.0027224125
11442379.65,11.504550575,1000.044,63.096458527493,3.00128842085064,1.38347976267976e-07,5.06747838641425e-05,5.32462477915649e-06,5.067255427175454e-08,5.324390505974227e-09,5.09537569637054e-05,5.99831177558481,1.53895571475505e-08,5.90675474512156e-11,1.53896705024145e-08,0.219909158150856,504,25,5,13.4965986394558,-0.076805167652275,0.0001336687557558,4369,0,11.5039091,11.5050182,1000.044,1000.044,11.479175,11.504550575
11442701.14,11.5011051875,1000.044,501.189655172414,3.00047285468784,2.48241515574587e-08,2.94494955216948e-05,2.46962089649931e-05,2.9448199800903563e-08,2.46951223796084e-08,3.84340412099083e-05,39.9830393862141,1.53897934910636e-08,-9.082776076200629e-11,1.5390061513188e-08,-0.338145338795869,501,25,5,13.4965986394558,-0.076805167652275,0.0003656204557051,4369,0,11.4997559,11.5019703,1000.044,1000.044,11.4763625,11.5011051875
11443021.75,11.501343975,1000.044,3981.09972041007,2.99944376723863,1.07146420836251e-08,2.62399687746938e-06,7.14372251044033e-06,2.623881426686606e-09,7.1434082004795084e-09,7.6103962392993e-06,69.8309558471147,1.53511443245333e-08,-1.2661872324627802e-09,1.54032743980071e-08,-4.71517518034312,568,25,5,13.4965986394558,-0.076805167652275,0.0020620640692313,4369,0,11.5010023,11.5023575,1000.044,1000.044,11.4742125,11.501343975
11443539.06,12.0063221625,1000.044,25.1190587138863,3.00129947782247,5.49657592752331e-07,4.91800189915895e-05,8.1233327208723e-07,4.91778551659622e-08,8.122975309958662e-10,4.91867274105326e-05,0.946299674252055,1.53926864787239e-08,2.5254627168536097e-11,1.53927071962174e-08,0.0940045295910387,400,25,5,13.4965986394558,-0.076805167652275,0.0001132023563603,4369,0,12.0055847,12.0073128,1000.044,1000.044,11.98305,12.0063221625
11443854.39,12.0018711,1000.044,199.530288909599,3.00117017116012,4.62949002632871e-08,4.58901906306589e-05,1.28061513550557e-05,4.588817155111065e-08,1.2805587909187697e-08,4.76435421505035e-05,15.5923320009191,1.53891152620449e-08,-3.04855142443329e-11,1.53891454575971e-08,-0.113501587837561,398,25,5,13.4965986394558,-0.076805167652275,0.0002080980733927,4369,0,12.000659,12.0030603,1000.044,1000.044,11.9793,12.0018711
11444177.05,12.0009881375,1000.044,1584.90027958993,3.00135812293117,1.70495921511948e-08,9.59467984452016e-06,1.77408179467202e-05,9.594257697181484e-09,1.7740037385075254e-08,2.01691472982253e-05,61.5943641290418,1.53828376514474e-08,-4.92600381664952e-10,1.53907228337984e-08,-1.83414022647486,528,25,5,13.4965986394558,-0.076805167652275,0.0009158528422177,4369,0,12.0005932,12.0013113,1000.044,1000.044,11.978075,12.0009881375
11444697.65,12.51005925,1000.044,10.0,3.00130123023475,1.00557421037922e-06,4.66857018468594e-05,-5.81605943173108e-06,4.6683647766357684e-08,-5.81580353637548e-09,4.70465865313019e-05,-7.10126636611972,1.528928565854e-08,1.7363182449793798e-11,1.52892955177321e-08,0.0650675687426485,320,25,5,13.4965986394558,-0.076805167652275,0.0001032422979458,4369,0,12.5096684,12.5102911,1000.044,1000.044,12.4866,12.51005925
11445016.73,12.5035737625,1000.044,79.4333643988816,3.00128073596109,7.30665636372408e-08,4.74262904564869e-05,4.18288038933436e-06,4.742420379152008e-08,4.1826963506949294e-09,4.76103929285879e-05,5.04030251136839,1.53991323545519e-08,7.45140126953767e-11,1.53993126343709e-08,0.277243225322022,316,25,5,13.4965986394558,-0.076805167652275,0.0001422689420917,4369,0,12.5033531,12.5037889,1000.044,1000.044,12.4803375,12.5035737625
11445340.47,12.5018135375,1000.044,630.960391425909,2.99998845647009,1.77792951917437e-08,3.14431323194267e-05,2.18753361786585e-05,3.144174888247587e-08,2.1874373706215425e-08,3.83040585706829e-05,34.8267642831318,1.53955395017666e-08,-1.18474789387447e-10,1.53959953502908e-08,-0.440905069896303,210,25,5,13.4965986394558,-0.076805167652275,0.0004337989113704,4369,0,12.5016212,12.5020409,1000.044,1000.044,12.4779375,12.5018135375
11445663.9,12.5012744625,1000.044,5011.89934762349,2.99865903132609,1.32058056593583e-08,2.90639882290372e-06,7.8946774494685e-06,2.906270946982053e-09,7.894330098944147e-09,8.41267413780675e-06,69.7889864182205,1.53317001074111e-08,-1.5965412182400302e-09,1.54146025587794e-08,-5.94497435591234,455,25,5,13.4965986394558,-0.076805167652275,0.0025561228733781,4369,0,12.500988,12.5017204,1000.044,1000.044,12.4761875,12.5012744625
11446178.27,13.00604895,1000.044,31.6230195712954,3.00129825981149,3.5893603908644e-07,4.52982735769945e-05,1.06719254744276e-06,4.529628054065071e-08,1.0671455930366664e-09,4.53108429516551e-05,1.34959492118722,1.54044688845615e-08,3.9979257941026797e-11,1.54045207636099e-08,0.148699550911134,496,25,5,13.4965986394558,-0.076805167652275,0.0001161157486585,4369,0,13.005168,13.006609,1000.044,1000.044,12.9845625,13.00604895
11446494.68,13.0017100375,1000.044,251.189655172414,3.00109333704547,4.51297178569285e-08,4.34791127093264e-05,1.0120884557495e-05,4.3477199712539044e-08,1.012043925816764e-08,4.46415226691077e-05,13.1037227957243,1.53801659560623e-08,-3.8432826711021493e-11,1.53802139750456e-08,-0.143173629479804,502,25,5,13.4965986394558,-0.076805167652275,0.0002356670803492,4369,0,13.0009899,13.0022697,1000.044,1000.044,12.9825125,13.0017100375
11446812.15,13.0020312125,1000.044,1995.30009319664,3.00069531719102,3.51852284725917e-08,1.13472218729939e-05,1.8264112756429e-05,1.1346722617198744e-08,1.8263309170825484e-08,2.15020291836492e-05,58.1479300018848,1.538014600666e-08,-6.25082369837628e-10,1.53928431147485e-08,-2.32734343431565,399,25,5,13.4965986394558,-0.076805167652275,0.0011185581954254,4369,0,13.0005093,13.0035515,1000.044,1000.044,12.979775,13.0020312125
11447330.97,13.508631725,1000.044,12.5890027958993,3.00130103721641,6.68534857366508e-07,4.80662264534414e-05,-2.74762784644179e-06,4.806411163252957e-08,-2.74750695613572e-09,4.81446942482352e-05,-3.27165982348481,1.54177148394811e-08,1.65853401969493e-11,1.5417723760175e-08,0.0616349205064826,384,25,5,13.4965986394558,-0.076805167652275,0.000105161590675,4369,0,13.5077496,13.5095558,1000.044,1000.044,13.487675,13.508631725
11447649.67,13.50303805,1000.044,100.0,3.00126855660348,7.55551611563468e-08,4.36594875777044e-05,2.66614032960483e-06,4.365756664477203e-08,2.666023024591748e-09,4.37408180056669e-05,3.49452397639902,1.53823181251313e-08,1.01065553865525e-10,1.53826501341258e-08,0.37644172498858,400,25,5,13.4965986394558,-0.076805167652275,0.0001525516464704,4369,0,13.5026064,13.5035915,1000.044,1000.044,13.48245,13.50303805
11447972.47,13.501535325,1000.044,794.330848089469,2.99922120559246,1.35179613702088e-08,3.21739465750664e-05,1.90987661042808e-05,3.217253098370312e-08,1.9097925795545794e-08,3.74155810448168e-05,30.6937779637707,1.54027460096986e-08,-1.53778400839054e-10,1.54035136392919e-08,-0.572012329114955,264,25,5,13.4965986394558,-0.076805167652275,0.0005184132222714,4369,0,13.5005713,13.5023766,1000.044,1000.044,13.4812375,13.501535325
11448290.17,13.5020042875,1000.044,6309.59972041006,3.00156376687455,1.27284473435946e-08,3.2607106367111e-06,8.45717390087462e-06,3.260567171755543e-09,8.45680180159535e-09,9.06399604181267e-06,68.9155761621853,1.52999682909891e-08,-2.01395764037444e-09,1.54319491666638e-08,-7.49881692091532,573,25,5,13.4965986394558,-0.076805167652275,0.0031708569208704,4369,0,13.5007925,13.5029278,1000.044,1000.044,13.47875,13.5020042875
11448803.2,14.005221225,1000.044,39.8108108108108,3.00129632945247,2.60883731821116e-07,4.30375196477619e-05,9.17745646776993e-07,4.303562608021437e-08,9.177052677452122e-10,4.3047303684478e-05,1.22160813506285,1.53895266304806e-08,4.6351807963862e-11,1.53895964339671e-08,0.172568981638482,312,25,5,13.4965986394558,-0.076805167652275,0.0001205308230266,4369,0,14.005023,14.0054302,1000.044,1000.044,13.9828375,14.005221225
11449123.78,14.0020025,1000.044,316.22972972973,3.00097156658191,6.3892184283262e-08,4.09953380091432e-05,8.22815001154595e-06,4.099353429363428e-08,8.22778798887444e-09,4.18129189497266e-05,11.3490098954347,1.538426386132e-08,-5.252001663050309e-11,1.53843535095519e-08,-0.195600103448385,316,25,5,13.4965986394558,-0.076805167652275,0.0002699734897457,4369,0,14.0016356,14.0022898,1000.044,1000.044,13.9795625,14.0020025
11449442.47,14.0013456375,1000.044,2511.90074557316,3.00138250558532,1.11959259635393e-08,1.27646368152799e-05,1.82797326466217e-05,1.2764075195971277e-08,1.8278928373773254e-08,2.2295393664566e-05,55.0736147820633,1.53735607896698e-08,-7.926085378651501e-10,1.53939793311531e-08,-2.95136249900418,502,25,5,13.4965986394558,-0.076805167652275,0.001373446835297,4369,0,14.0010643,14.0017548,1000.044,1000.044,13.9777,14.0013456375
11449964.07,14.5094492375,1000.044,15.8490214352283,3.00130073123969,6.29732675554251e-07,4.14452042041975e-05,-3.15515320207432e-08,4.1443380695446897e-08,-3.155014381441537e-11,4.14452162140192e-05,-0.043618298122567,1.53988644601651e-08,-6.0943388537058594e-12,1.53988656661295e-08,-0.0226756900103169,480,25,5,13.4965986394558,-0.076805167652275,0.0001072761076002,4369,0,14.5079746,14.5105143,1000.044,1000.044,14.4842,14.5094492375
11450284.68,14.5042556625,1000.044,125.890027958993,3.00124925555362,6.82544585305205e-08,4.12868340984605e-05,2.81362306409574e-06,4.128501755768796e-08,2.8134992701278545e-09,4.13825947062363e-05,3.89857596899526,1.5379019585342e-08,-1.27868505596941e-11,1.53790249011399e-08,-0.047638433480472,500,25,5,13.4965986394558,-0.076805167652275,0.0001675824268516,4369,0,14.5035009,14.5049486,1000.044,1000.044,14.477125,14.5042556625
11450602.65,14.502448425,1000.044,1000.0,2.99800636951636,2.03507532614964e-08,3.19909139768651e-05,1.67145880765571e-05,3.198950643858181e-08,1.671385266703975e-08,3.60942659108641e-05,27.5861328113339,1.54153093040149e-08,-1.988050791586e-10,1.54165912055145e-08,-0.738879792241789,333,25,5,13.4965986394558,-0.076805167652275,0.0006228469400928,4369,0,14.5016336,14.5030832,1000.044,1000.044,14.4749875,14.502448425
11450949.99,14.5026460875,1000.044,7943.30009319665,2.99927656587788,1.10174249135121e-08,3.54544084360037e-06,8.82511929881062e-06,3.5452848510669235e-09,8.824731010646152e-09,9.51067197487693e-06,68.1124892811442,1.52540903905111e-08,-2.52502155259154e-09,1.5461662507083e-08,-9.39898827901862,611,5,5,13.4965986394558,-0.076805167652275,0.0039140278736904,4369,0,14.5015745,14.5042925,1000.044,1000.044,14.47215,14.5026460875
11451435.84,15.0071739125,1000.044,50.118825722274,3.00129326999639,6.07753108413957e-07,4.01045274320588e-05,1.11894816378246e-06,4.010276291049074e-08,1.118898932229442e-09,4.01201341665502e-05,1.59818313089469,1.53905502580681e-08,6.58017010715738e-11,1.53906909237365e-08,0.244964391845572,400,25,5,13.4965986394558,-0.076805167652275,0.0001258324557415,4369,0,15.0067539,15.0075026,1000.044,1000.044,14.972925,15.0071739125
11451757.18,15.0031749125,1000.044,398.109972041007,3.00077860318821,2.47345878291311e-08,3.8689121905439e-05,6.91825706598833e-06,3.8687419658974e-08,6.917952676070583e-09,3.9302804411963e-05,10.1382840273699,1.53842335680184e-08,-6.865430915810569e-11,1.5384386757018e-08,-0.255688788803809,398,25,5,13.4965986394558,-0.076805167652275,0.0003128958358398,4369,0,15.0026436,15.0036087,1000.044,1000.044,14.9687,15.0031749125
11452078.62,15.0018803125,1000.044,3162.30009319665,3.00179839873488,1.95241631264118e-08,1.37817583708394e-05,1.78298987266995e-05,1.3781152000151394e-08,1.7829114245672692e-08,2.25353533896534e-05,52.2974922117566,1.53641854582962e-08,-1.00136300246073e-09,1.53967828671972e-08,-3.72898666253337,451,25,5,13.4965986394558,-0.076805167652275,0.0016913075726189,4369,0,15.0014505,15.0020838,1000.044,1000.044,14.9661875,15.0018803125
11452594.09,15.5118131875,1000.044,19.952935694315,3.00130024631558,5.36258142419939e-07,3.82589952514462e-05,6.36737433005501e-07,3.8257311929721296e-08,6.367094177911182e-10,3.82642934366855e-05,0.953475112275216,1.53589710866226e-08,2.9802383813207195e-11,1.53590000007094e-08,0.111175980426093,304,25,5,13.4965986394558,-0.076805167652275,0.0001091382594255,4369,0,15.510643,15.5123978,1000.044,1000.044,15.47765,15.5118131875
11452919.32,15.5036665625,1000.044,158.490214352283,3.00121865985064,4.24021527470932e-08,3.85383804235627e-05,2.40045419213775e-06,3.8536684809431085e-08,2.400348576800371e-09,3.86130670369474e-05,3.56419856727952,1.53811093798041e-08,-1.70803024569511e-11,1.53811188634062e-08,-0.0636253742925987,316,25,5,13.4965986394558,-0.076805167652275,0.0001845832626323,4369,0,15.5031548,15.5054913,1000.044,1000.044,15.4705625,15.5036665625
11453238.12,15.50202905,1000.044,1258.90027958993,3.00024530415142,4.30348370122293e-08,3.13235675370802e-05,1.48695816749009e-05,3.132218936074833e-08,1.4868927442093447e-08,3.46737702368314e-05,25.3941162077176,1.53817463851162e-08,-3.8606263587860603e-10,1.53865904675096e-08,-1.43775070159967,419,25,5,13.4965986394558,-0.076805167652275,0.0007659861167818,4369,0,15.5002584,15.5033016,1000.044,1000.044,15.467625,15.50202905
11453587.73,15.502242325,1000.044,10000.0,2.99869557976582,1.10191855079418e-08,3.85202293482315e-06,9.06439793108204e-06,3.8518534532712065e-09,9.063999115120975e-09,9.84892839568894e-06,66.9763614677134,1.51887898316184e-08,-3.20233070327562e-09,1.55227013912597e-08,-11.9056006180598,588,5,5,13.4965986394558,-0.076805167652275,0.0047906703105995,4369,0,15.5018053,15.5027771,1000.044,1000.044,15.464025,15.502242325
11454075.84,16.007387175,1000.044,63.096458527493,3.00128842085064,1.76369784591156e-07,3.75331963174952e-05,4.9765854088777e-07,3.75315449295183e-08,4.976366448753955e-10,3.7536495438852e-05,0.759649218572029,1.53883204994683e-08,6.139872747367409e-11,1.53884429881028e-08,0.2286064476008,504,25,5,13.4965986394558,-0.076805167652275,0.0001325244237192,4369,0,16.0068417,16.0077515,1000.044,1000.044,15.9695,16.007387175
11454395.96,16.00300955,1000.044,501.189655172414,3.00047285468784,2.13711883593263e-08,3.65024635818087e-05,5.96185634539538e-06,3.650085754407676e-08,5.961594035257829e-09,3.69861268399977e-05,9.27607301364573,1.53884462842489e-08,-9.040880949482519e-11,1.53887118627924e-08,-0.336615115048403,501,25,5,13.4965986394558,-0.076805167652275,0.0003667263923823,4369,0,16.0026283,16.0033283,1000.044,1000.044,15.96505,16.00300955
11454717.01,16.0022525875,1000.044,3981.09972041007,2.99944376723863,1.61144496118948e-08,1.4589088542438e-05,1.72306266385542e-05,1.4588446650785366e-08,1.722986852433913e-08,2.25773337410853e-05,49.7455715519671,1.53497111624913e-08,-1.2655941504393502e-09,1.54017973407501e-08,-4.71341459959223,568,25,5,13.4965986394558,-0.076805167652275,0.0020890671245499,4369,0,16.0015774,16.0030632,1000.044,1000.044,15.9621125,16.0022525875
11455239.18,16.51092435,1000.044,25.1190587138863,3.00130051557494,5.96968791314088e-07,3.62974438206292e-05,2.55457216759951e-07,3.6295846803369855e-08,2.55445977136957e-10,3.62983427486893e-05,0.403234420212666,1.53845776050944e-08,2.2416878135702297e-11,1.53845939369097e-08,0.0834856588865971,400,25,5,13.4965986394558,-0.076805167652275,0.0001119726910443,4369,0,16.5098896,16.5121822,1000.044,1000.044,16.474625,16.51092435
11455559.58,16.504507575,1000.044,199.530288909599,3.00117124649068,3.26297559297887e-08,3.63555221356311e-05,2.0329338617642e-06,3.635392256303832e-08,2.032844416609869e-09,3.64123167326753e-05,3.20054141624996,1.53799709687192e-08,-2.7130755909650397e-11,1.53799948984569e-08,-0.101071464918562,398,25,5,13.4965986394558,-0.076805167652275,0.0002059118339382,4369,0,16.5038815,16.5057583,1000.044,1000.044,16.4678875,16.504507575
11455881.14,16.5021130625,1000.044,1584.90027958993,3.00135920227642,2.22328608226574e-08,3.04538119600532e-05,1.30437101025872e-05,3.0452472051282947e-08,1.3043136204594198e-08,3.31296398431769e-05,23.1859951065005,1.53817506916227e-08,-4.92047832282862e-10,1.5389618754488e-08,-1.83221365298721,528,25,5,13.4965986394558,-0.076805167652275,0.0009336843671758,4369,0,16.5013847,16.5028419,1000.044,1000.044,16.4649375,16.5021130625
11456397.45,17.01558925,1000.044,10.0,3.00129574845983,1.08560695822869e-06,2.67391898498809e-05,4.68138409981972e-06,2.67380133772923e-08,4.681178127982089e-09,2.71458952867284e-05,9.93045743530252,1.55210945931249e-08,2.19249017294737e-10,1.55226430578145e-08,0.809299101516545,320,25,5,13.4965986394558,-0.076805167652275,0.0001024473977382,4369,0,17.0139885,17.0197716,1000.044,1000.044,16.9773,17.01558925
11456711.91,17.008134375,1000.044,79.4333643988816,3.00127549342772,5.5190436311376e-08,3.55869264131959e-05,7.46452835619173e-07,3.558536065732698e-08,7.464199931394749e-10,3.55947541552688e-05,1.20163022608436,1.53910501573823e-08,7.414432604379719e-11,1.53912287465342e-08,0.276012621089405,316,25,5,13.4965986394558,-0.076805167652275,0.000141327177984,4369,0,17.0074005,17.0087357,1000.044,1000.044,16.9678375,17.008134375
11457030.57,17.0036406625,1000.044,630.960391425909,2.99998330969594,1.84477526848738e-08,3.45660799639611e-05,5.11453195679643e-06,3.456455912335967e-08,5.114306927291629e-09,3.49424143586565e-05,8.41663875546771,1.53938828753393e-08,-1.18378238851332e-10,1.53943380301687e-08,-0.440593178170445,210,25,5,13.4965986394558,-0.076805167652275,0.0004345997345946,4369,0,17.0031052,17.0039368,1000.044,1000.044,16.9639625,17.0036406625
11457348.98,17.0027191625,1000.044,5011.89934762349,2.99865417128658,6.5981347946853105e-09,1.51938123439959e-05,1.65029721992067e-05,1.519314384566669e-08,1.6502246100378285e-08,2.24321203846706e-05,47.3651208207115,1.53304721080212e-08,-1.5951002903851401e-09,1.54132319774667e-08,-5.94011958340116,455,25,5,13.4965986394558,-0.076805167652275,0.002590741725614,4369,0,17.0020409,17.0032673,1000.044,1000.044,16.9617,17.0027191625
11457899.19,18.0082578625,1000.044,31.6230195712954,3.00126267198606,2.9861186560372e-07,3.3230737866369e-05,-2.05933009557666e-07,3.322927577823476e-08,-2.0592394890391423e-10,3.32313759502636e-05,-0.35506106781196,1.53774512907954e-08,4.92962525849404e-11,1.53775303063042e-08,0.18367527167242,496,25,5,13.4965986394558,-0.076805167652275,0.0001157490555993,4369,0,18.0079479,18.008522,1000.044,1000.044,17.978125,18.0082578625
11458217.49,18.00339745,1000.044,251.189655172414,3.00105796514479,3.01180223775546e-08,3.34603379898589e-05,1.49048295688091e-06,3.345886579976371e-08,1.4904173785162553e-09,3.34935181466556e-05,2.55054107700702,1.53788342588658e-08,-3.9889284272601395e-11,1.53788859907558e-08,-0.148612207714905,502,25,5,13.4965986394558,-0.076805167652275,0.0002339075126292,4369,0,18.0032024,18.0035973,1000.044,1000.044,17.9737125,18.00339745
11458541.18,18.001744975,1000.044,1995.30009319664,3.00066029031938,3.21820393795317e-08,2.98350495363226e-05,1.0017375505412e-05,2.983373685190111e-08,1.0016934760282548e-08,3.14718603334987e-05,18.5599212868441,1.53780496517397e-08,-6.24326285240677e-10,1.53907178000837e-08,-2.32484796095309,399,25,5,13.4965986394558,-0.076805167652275,0.0011404318606232,4369,0,18.0014858,18.0023155,1000.044,1000.044,17.97115,18.001744975
11459092.83,19.010115875,1000.044,12.5890027958993,3.00121040082206,9.23228613158859e-07,3.245066336155e-05,8.01785801256006e-07,3.2449235595183814e-08,8.017505242329398e-10,3.24605670479697e-05,1.41536698859599,1.54233578831339e-08,1.22977329667303e-12,1.54233579321616e-08,0.0045684487153725,384,25,5,13.4965986394558,-0.076805167652275,0.0001048547509575,4369,0,19.0095654,19.0113602,1000.044,1000.044,18.9839625,19.010115875
11459409.84,19.004659875,1000.044,100.0,3.00117840568085,8.5814183367639e-08,3.20531242472063e-05,3.07107085344216e-07,3.205171397179154e-08,3.07093573226994e-10,3.20545954391677e-05,0.548944973713645,1.53955044849701e-08,8.448017505771059e-11,1.5395736268419e-08,0.314397550703876,400,25,5,13.4965986394558,-0.076805167652275,0.0001517200078698,4369,0,19.0044498,19.005064,1000.044,1000.044,18.9783,19.004659875
11459729.68,19.0017884,1000.044,794.330848089469,2.99913144219064,1.78769643554258e-08,3.13386651917527e-05,3.07193605420504e-06,3.133728635115325e-08,3.0718008949656613e-09,3.14888667170144e-05,5.59846631044739,1.54018106291794e-08,-1.53108256440279e-10,1.54025716292862e-08,-0.569554331005293,264,25,5,13.4965986394558,-0.076805167652275,0.0005179249745697,4369,0,19.0015221,19.0023823,1000.044,1000.044,18.9761,19.0017884
11460050.41,19.002068975,1000.044,6309.59972041006,3.00148100345214,8.83014363191138e-09,1.9835301951228e-05,1.46022392009509e-05,1.9834429236341603e-08,1.460159673069475e-08,2.46305621774692e-05,36.3595448446823,1.52989009038002e-08,-2.0109528739786e-09,1.5430499030351e-08,-7.48827243163163,573,25,5,13.4965986394558,-0.076805167652275,0.0032263818385706,4369,0,19.0015087,19.0026531,1000.044,1000.044,18.9735,19.002068975
11460640.48,20.0069849375,1000.044,39.8108108108108,3.00112594495381,1.48483083399673e-07,3.02611859835388e-05,1.2318684837604e-07,3.0259854549938603e-08,1.231814283931907e-10,3.02614367162225e-05,0.233237637164963,1.53852051157931e-08,4.5169598518901596e-11,1.5385271422619e-08,0.16821484680215,312,25,5,13.4965986394558,-0.076805167652275,0.0001202013307125,4369,0,20.00597,20.0075817,1000.044,1000.044,19.9801125,20.0069849375
11460962.27,20.002783775,1000.044,316.22972972973,3.00080150076318,2.99646821183506e-08,3.01274794194151e-05,8.06276996059332e-07,3.012615386864488e-08,8.06241521432389e-10,3.01382663529549e-05,1.53299399124611,1.53836145231709e-08,-5.1901027164596393e-11,1.53837020744077e-08,-0.193302979728117,316,25,5,13.4965986394558,-0.076805167652275,0.0002676536970234,4369,0,20.0015907,20.003912,1000.044,1000.044,19.974875,20.002783775
11461284.05,20.000955325,1000.044,2511.90074557316,3.00121474025947,1.54415133270737e-08,2.86557834811714e-05,6.24328493001698e-06,2.8654522682173384e-08,6.243010237566527e-09,2.93280161899361e-05,12.2910549373331,1.53723972314012e-08,-7.91674464376123e-10,1.53927692471997e-08,-2.94811325143007,502,25,5,13.4965986394558,-0.076805167652275,0.0013982283329231,4369,0,19.9996319,20.0019531,1000.044,1000.044,19.973725,20.000955325
11461834.02,21.0167918125,1000.044,15.8490214352283,3.00102247206407,4.3761607370731e-07,2.92013654596136e-05,-1.63649408244175e-07,2.9200080656064736e-08,-1.6364220798702358e-10,2.92018240155428e-05,-0.321091911477822,1.54169974199053e-08,4.74210944205633e-12,1.54169981492172e-08,0.0176235904469591,480,25,5,13.4965986394558,-0.076805167652275,0.0001068214082069,4369,0,21.0119324,21.0194397,1000.044,1000.044,20.9768125,21.0167918125
11462151.01,21.0073785625,1000.044,125.890027958993,3.00097242045741,5.92802002663178e-08,2.88224748289758e-05,2.89236644828082e-07,2.8821206695881182e-08,2.8922391897564703e-10,2.88239260529106e-05,0.574950030289692,1.53798529544935e-08,-1.20378781863465e-11,1.53798576655428e-08,-0.0448456481062749,500,25,5,13.4965986394558,-0.076805167652275,0.0001661822163139,4369,0,21.0061054,21.0085182,1000.044,1000.044,20.9693125,21.0073785625
11462469.56,21.0040297375,1000.044,1000.0,3.00189398576035,1.70305044460458e-08,2.86765404809325e-05,1.77443614144483e-06,2.8675278768666676e-08,1.7743580696897636e-09,2.87313869761734e-05,3.5408121424375,1.54143691641422e-08,-1.98368877740732e-10,1.54156455245998e-08,-0.737303744649068,333,25,5,13.4965986394558,-0.076805167652275,0.0006219429635821,4369,0,21.003294,21.0054359,1000.044,1000.044,20.9655125,21.0040297375
11462815.93,21.002724425,1000.044,7943.30009319665,2.99903359100389,9.548466864860442e-09,2.31941877584312e-05,1.07326264228928e-05,2.31931672590718e-08,1.0732154208107645e-08,2.55569876101769e-05,24.8313554191498,1.52534439242621e-08,-2.5198533682674103e-09,1.54601815173101e-08,-9.38048326288765,611,5,5,13.4965986394558,-0.076805167652275,0.0039916845204807,4369,0,20.999815,21.0039616,1000.044,1000.044,20.9630125,21.002724425
11463331.05,22.0128896375,1000.044,50.118825722274,3.00088120430448,7.43676492949497e-07,2.70067385789345e-05,-1.67923633759722e-07,2.7005550334719772e-08,-1.679162454449224e-10,2.70072606352012e-05,-0.356251513969426,1.54000377088035e-08,5.0660882787036195e-11,1.54001210371092e-08,0.188482934545304,400,25,5,13.4965986394558,-0.076805167652275,0.0001250614437267,4369,0,22.011879,22.0133095,1000.044,1000.044,21.964075,22.0128896375
11463647.88,22.00519015,1000.044,398.109972041007,3.000367908441,1.95092110572074e-08,2.75836434688205e-05,4.91368886284861e-07,2.7582429841907458e-08,4.913472670051128e-10,2.75880196896663e-05,1.0205463245515,1.53838099817421e-08,-6.98392593562975e-11,1.53839685086943e-08,-0.260108992549306,398,25,5,13.4965986394558,-0.076805167652275,0.0003103453335256,4369,0,22.0039577,22.0066109,1000.044,1000.044,21.9571625,22.00519015
11463961.38,22.0031476,1000.044,3162.30009319665,3.00139636789787,1.57375079018031e-08,2.69585897937562e-05,3.51591691928192e-06,2.695740366799481e-08,3.515762225743987e-09,2.71868945532827e-05,7.4305284264699,1.53629955275569e-08,-1.0003574493268901e-09,1.53955300852604e-08,-3.72554034606208,451,25,5,13.4965986394558,-0.076805167652275,0.0017221533133994,4369,0,22.0028515,22.0037289,1000.044,1000.044,21.953775,22.0031476
11464168.58,22.003568175,1000.044,10000.0,2.99835877175253,1.9650997044103e-08,2.33754876290565e-05,9.20433455967204e-06,2.3374459152853774e-08,9.203929586770222e-09,2.51223644703787e-05,21.4925414953568,1.51919143944511e-08,-3.1912685645237603e-09,1.55234808602726e-08,-11.8632703879613,588,5,5,13.4965986394558,-0.076805167652275,0.0048901187118829,4369,0,22.0023479,22.0051765,1000.044,1000.044,21.9519875,22.003568175