File: Hello.txt
Comment,Time Stamp (sec),Temperature (K),Magnetic Field (Oe),Frequency (Hz),Amplitude (Oe),M-DC (emu),M-Std.Dev. (emu),M' (emu),M'' (emu),Moment (emu),Phase (deg),Calcoil' (emu),Calcoil'' (emu),Calcoil (emu),CC Phase (deg),Count,Gain,Measure Type,Elapsed (sec),Sample Center (cm),Max.Signal (V),PPMS Status (code),DSP Status (code),Min.Temperature (K),Max.Temperature (K),Min.Field (Oe),Max.Field (Oe),DC Position (cm),PPMS Temperature (K),PPMS Position,Bridge 1 Resistance (ohms),Bridge 1 Excitation (uA),Bridge 2 Resistance (ohms),Bridge 2 Excitation (uA),Bridge 3 Resistance (ohms),Bridge 3 Excitation (uA),Bridge 4 Resistance (ohms),Bridge 4 Excitation (uA),Signal 1 Vin (V),Signal 2 Vin (V),Digital Inputs (code),Drive 1 Iout (mA),Drive 1 Ipower (watts),Drive 2 Iout (mA),Drive 2 Ipower (watts),Pressure (),Map 20 (),Map 21 (),Map 22 (),Map 23 (),Map 24 (),Map 25 (),Map 26 (),Map 27 (),Map 28 (),Map 29 ()
,11370981.41,2.2038750625,-0.024,10.0,3.00137149090889,,8.49055824541675e-07,0.0002449586808517,2.59835717661919e-06,0.0002449724612781,0.607732357854336,1.53220075445928e-08,2.7829503731090197e-11,1.53220328180642e-08,0.104066738753131,320,25,5,13.4965986394558,-0.076805167652275,0.0001015050497201,4369,0,2.2029238,2.2048819,-0.024,-0.024,,2.19685,,,,,,,,,,,,,,,,,,,,,,,2.2038750625,,,,
,11371292.31,2.1982869375,-0.024,79.4333643988816,3.00135099520827,,2.70645651262771e-07,0.0002302772773189,4.81016785723102e-05,0.0002352475205626,11.7986288953617,1.53928649622125e-08,7.05373058441449e-11,1.53930265788254e-08,0.262554218741938,316,25,5,13.4965986394558,-0.076805167652275,0.0001460276569448,4369,0,2.197299,2.1996496,-0.024,-0.024,,2.19325,,,,,,,,,,,,,,,,,,,,,,,2.1982869375,,,,
,11371606.42,2.199694175,-0.024,630.960391425909,3.00005862577851,,2.44768863213435e-08,0.0001019988486306,7.8946096468439e-05,0.0001289815927548,37.7395154593485,1.53941980200004e-08,-1.19208261057424e-10,1.53946595703994e-08,-0.443673240695773,210,25,5,13.4965986394558,-0.076805167652275,0.0004550709351639,4373,0,2.1991463,2.2004805,-0.024,-0.024,,2.1946,,,,,,,,,,,,,,,,,,,,,,,2.199694175,,,,
,11371920.25,2.205847625,-0.024,5011.89934762349,2.99872559688416,,1.41218172716399e-08,2.65889107931947e-05,3.04671059227564e-05,4.04377882738031e-05,48.8885110714484,1.53317638790357e-08,-1.5978356943588201e-09,1.54148001138085e-08,-5.94973540946972,455,25,5,13.4965986394558,-0.076805167652275,0.0026182151568369,4373,0,2.2034225,2.2065904,-0.024,-0.024,,2.1846125,,,,,,,,,,,,,,,,,,,,,,,2.205847625,,,,
,11372616.2,2.99873155,-0.024,31.6230195712954,3.00136852027881,,3.22637131029646e-07,0.0001792400778656,1.57698246140985e-05,0.0001799324675584,5.02802610027091,1.53668032134333e-08,3.8280186093859596e-11,1.53668508931736e-08,0.142729007122445,496,25,5,13.4965986394558,-0.076805167652275,0.0001161609209918,4369,0,2.9968536,3.0018446,-0.024,-0.024,,2.9988375,,,,,,,,,,,,,,,,,,,,,,,2.99873155,,,,
,11372926.61,2.9945782625,-0.024,251.189655172414,3.00116358324547,,9.22494401623607e-08,0.0001234848216095,6.14942419825139e-05,0.0001379494217637,26.4728587712022,1.53845629601003e-08,-3.9371775496284294e-11,1.53846133396325e-08,-0.146629556456844,502,25,5,13.4965986394558,-0.076805167652275,0.0002439897148947,4373,0,2.9552896,3.0294523,-0.024,-0.024,,3.002275,,,,,,,,,,,,,,,,,,,,,,,2.9945782625,,,,
,11373238.29,3.0013818875,-0.024,1995.30009319664,3.00076496165185,,2.66374246854003e-08,3.68442215909406e-05,3.77473765192596e-05,5.27480909486693e-05,45.6937032910993,1.53818600450796e-08,-6.26071861841889e-10,1.53945959486635e-08,-2.33076404319439,399,25,5,13.4965986394558,-0.076805167652275,0.001144384447119,4373,0,2.9965498,3.0062432,-0.024,-0.024,,3.0029875,,,,,,,,,,,,,,,,,,,,,,,3.0013818875,,,,
,11373777.89,3.9987389,-0.024,12.5890027958993,3.00137129787711,,1.10606577847639e-06,0.0001369521252792,4.93477790360835e-06,0.0001370410035407,2.0636384701022,1.53759869508423e-08,1.3354041490710199e-11,1.53759927498323e-08,0.0497613601604472,384,25,5,13.4965986394558,-0.076805167652275,0.0001041188847895,4369,0,3.9927275,4.0040679,-0.024,-0.024,,4.0066625,,,,,,,,,,,,,,,,,,,,,,,3.9987389,,,,
,11374091.8,4.0863220625,-0.024,100.0,3.00133881500266,,1.36548981062786e-07,0.0001202123126138,3.01882447484754e-05,0.000123944867683,14.0968611142499,1.53845587472525e-08,9.008677655882069e-11,1.53848225038501e-08,0.335500886172584,400,25,5,13.4965986394558,-0.076805167652275,0.0001553819854479,4374,0,3.93031,4.2385397,-0.024,-0.024,,4.082025,,,,,,,,,,,,,,,,,,,,,,,4.0863220625,,,,
,11374407.37,3.9986078625,-0.024,794.330848089469,2.99929132153899,,2.61935492638609e-08,5.04127806135802e-05,4.19496423314846e-05,6.55836941696064e-05,39.7646260621787,1.54021010482765e-08,-1.54205522219211e-10,1.54028729802074e-08,-0.573625012193474,264,25,5,13.4965986394558,-0.076805167652275,0.0005255252639465,4369,0,3.9974515,3.9996972,-0.024,-0.024,,4.003975,,,,,,,,,,,,,,,,,,,,,,,3.9986078625,,,,
,11374718.94,4.00094125,-0.024,6309.59972041006,3.00162843652362,,7.665847794539981e-09,1.42322132271226e-05,1.61035502320578e-05,2.14913988241504e-05,48.5299595987611,1.52997334701131e-08,-2.0157869688286404e-09,1.54319552021187e-08,-7.50566454644456,573,25,5,13.4965986394558,-0.076805167652275,0.0032083364703301,4369,0,3.996603,4.0039849,-0.024,-0.024,,3.9967,,,,,,,,,,,,,,,,,,,,,,,4.00094125,,,,
,11375262.92,4.99819935,-0.024,39.8108108108108,3.00136658978538,,2.57943386998904e-07,0.0001070858953865,1.1328530198256e-05,0.0001076834462078,6.03881348124357,1.53799576896707e-08,4.90241542364855e-11,1.53800358225773e-08,0.182631687004405,312,25,5,13.4965986394558,-0.076805167652275,0.0001219442605685,4369,0,4.9898143,5.0044432,-0.024,-0.024,,4.998625,,,,,,,,,,,,,,,,,,,,,,,4.99819935,,,,
,11375571.66,4.99939685,-0.024,316.22972972973,3.00104180430481,,4.25733270794624e-08,6.91799889379969e-05,3.86942220645343e-05,7.92660942057881e-05,29.2194548387695,1.53848060462128e-08,-5.1839797194772094e-11,1.53848933842312e-08,-0.193059980097928,316,25,5,13.4965986394558,-0.076805167652275,0.0002751285846841,4369,0,4.9955592,5.0014343,-0.024,-0.024,,5.0030375,,,,,,,,,,,,,,,,,,,,,,,4.99939685,,,,
,11375886.33,5.001173025,-0.024,2511.90074557316,3.00145181849252,,1.26259672879257e-08,2.02111921118827e-05,2.11504995141955e-05,2.92546734092762e-05,46.300940525547,1.5374023969911e-08,-7.93418744228989e-10,1.53944836331425e-08,-2.95428519681468,502,25,5,13.4965986394558,-0.076805167652275,0.0013823717450364,4369,0,4.9993935,5.0035491,-0.024,-0.024,,5.001675,,,,,,,,,,,,,,,,,,,,,,,5.001173025,,,,
,11377371.61,5.495649275,-0.024,15.8490214352283,3.00137099187908,,5.40913864753318e-07,0.0001015412580478,3.75707254981006e-06,0.0001016107409681,2.11900315646349,1.54131714094868e-08,4.4633177363001094e-11,1.5413236033317e-08,0.165915597325947,480,25,5,13.4965986394558,-0.076805167652275,0.000110837370361,4369,0,5.4933538,5.4984503,-0.024,-0.024,,5.500025,,,,,,,,,,,,,,,,,,,,,,,5.495649275,,,,
,11377681.78,5.500323725,-0.024,125.890027958993,3.00131951260894,,8.50834308340684e-08,8.77899619631772e-05,2.54714940412578e-05,9.1410472212925e-05,16.1796267920142,1.53815855215128e-08,-1.0636142817331698e-11,1.53815891988815e-08,-0.0396191924265281,500,25,5,13.4965986394558,-0.076805167652275,0.0001729370723453,4369,0,5.4994082,5.500843,-0.024,-0.024,,5.506425,,,,,,,,,,,,,,,,,,,,,,,5.500323725,,,,
,11377993.83,5.4997995,-0.024,1000.0,2.99807640102726,,2.6567051651586e-08,3.28955856511942e-05,2.918164849603e-05,4.39737212921639e-05,41.5762072966632,1.54171758617025e-08,-1.99249651753538e-10,1.54184633467277e-08,-0.740442262591785,333,25,5,13.4965986394558,-0.076805167652275,0.0006252089943032,4369,0,5.4989557,5.5005093,-0.024,-0.024,,5.50485,,,,,,,,,,,,,,,,,,,,,,,5.4997995,,,,
,11378337.56,5.503335075,-0.024,7943.30009319665,2.99933830360841,,1.31757650359982e-08,9.4035022323196e-06,1.06189182306955e-05,1.41840501487917e-05,48.4737488884509,1.52546670714026e-08,-2.5286743230436904e-09,1.54628283729515e-08,-9.41199254325903,611,5,5,13.4965986394558,-0.076805167652275,0.0039399558449806,4369,0,5.5024805,5.5046387,-0.024,-0.024,,5.5008625,,,,,,,,,,,,,,,,,,,,,,,5.503335075,,,,
,11378825.27,5.9996912,-0.024,50.118825722274,3.00136353011628,,1.08409535991158e-06,8.9381352946495e-05,1.12689730892565e-05,9.0088933887755e-05,7.18579188101729,1.54139356702236e-08,5.8700347814315e-11,1.54140474430509e-08,0.218196442408655,400,25,5,13.4965986394558,-0.076805167652275,0.0001296446818148,4369,0,5.995564,6.0049782,-0.024,-0.024,,6.0075125,,,,,,,,,,,,,,,,,,,,,,,5.9996912,,,,
,11379138.07,6.003342975,-0.024,398.109972041007,3.0008488274793,,1.76115089675788e-08,5.34498826283072e-05,3.31295856277692e-05,6.28844924989262e-05,31.7916789721481,1.53871056015832e-08,-6.90667315223933e-11,1.5387260607648e-08,-0.257176739245153,398,25,5,13.4965986394558,-0.076805167652275,0.0003186200611063,4373,0,5.981719,6.012321,-0.024,-0.024,,6.01035,,,,,,,,,,,,,,,,,,,,,,,6.003342975,,,,
,11379451.04,6.003443725,-0.024,3162.30009319665,3.00186717732107,,1.16662302019197e-08,1.50121380599497e-05,1.62317501566658e-05,2.2109590730708e-05,47.2354184994607,1.53658634048062e-08,-1.00285177845668e-09,1.5398554148514e-08,-3.73410840071716,451,25,5,13.4965986394558,-0.076805167652275,0.001694438553242,4369,0,6.0019007,6.0051613,-0.024,-0.024,,6.0024125,,,,,,,,,,,,,,,,,,,,,,,6.003443725,,,,
,11379962.01,6.4982277125,-0.024,19.952935694315,3.00137050692122,,9.14076424908043e-07,8.42642968476653e-05,2.84041085976366e-06,8.43121560457549e-05,1.93061549346908,1.53778357583536e-08,2.37863521581516e-12,1.53778359423166e-08,0.0088624797352548,304,25,5,13.4965986394558,-0.076805167652275,0.0001113371870791,4369,0,6.4965825,6.4993157,-0.024,-0.024,,6.505125,,,,,,,,,,,,,,,,,,,,,,,6.4982277125,,,,
,11380271.32,6.499279675,-0.024,158.490214352283,3.00128891477575,,7.63642394512347e-08,7.27259430967279e-05,2.3408818790537e-05,7.64004947397378e-05,17.8421804231966,1.53821363697429e-08,-1.8555184027662497e-11,1.53821475611249e-08,-0.0691147959983596,316,25,5,13.4965986394558,-0.076805167652275,0.0001891911500821,4369,0,6.4976096,6.5005822,-0.024,-0.024,,6.5059375,,,,,,,,,,,,,,,,,,,,,,,6.499279675,,,,
,11380582.07,6.5002757375,-0.024,1258.90027958993,3.00031529927546,,7.66487288558809e-08,2.50775231890505e-05,2.38199446404992e-05,3.45871642661524e-05,43.5267526923871,1.53840197922562e-08,-3.87246690711726e-10,1.53888929091081e-08,-1.44194539820649,419,25,5,13.4965986394558,-0.076805167652275,0.0007634715950078,4369,0,6.4985175,6.5026112,-0.024,-0.024,,6.506625,,,,,,,,,,,,,,,,,,,,,,,6.5002757375,,,,
,11380923.58,6.503951375,-0.024,10000.0,2.99875322179749,,1.06566636066328e-08,7.2485053801552e-06,8.12969792709696e-06,1.08918693818822e-05,48.2795419939511,1.51902617812611e-08,-3.2060184303506103e-09,1.55249028067485e-08,-11.9177969888046,588,5,5,13.4965986394558,-0.076805167652275,0.0048150437760601,4369,0,6.5018611,6.5053496,-0.024,-0.024,,6.5018875,,,,,,,,,,,,,,,,,,,,,,,6.503951375,,,,
,11381432.02,7.0036465625,-0.024,63.096458527493,3.00135868063289,,3.16860666330048e-07,7.63620007002461e-05,9.96359678998762e-06,7.70092748436046e-05,7.43386901919356,1.53988549058769e-08,6.18239604351209e-11,1.53989790120752e-08,0.230032232597082,504,25,5,13.4965986394558,-0.076805167652275,0.0001367330342763,4373,0,6.9713612,7.0350051,-0.024,-0.024,,6.9976875,,,,,,,,,,,,,,,,,,,,,,,7.0036465625,,,,
,11381741.61,7.00042905,-0.024,501.189655172414,3.00054305769988,,2.79398924949084e-08,4.3301676076483e-05,2.9243198643831e-05,5.22513140308951e-05,34.0325897311035,1.53903345319404e-08,-9.119149694101819e-11,1.53906046955327e-08,-0.339487536584159,501,25,5,13.4965986394558,-0.076805167652275,0.0003714384613075,4369,0,6.9994841,7.0018287,-0.024,-0.024,,7.00595,,,,,,,,,,,,,,,,,,,,,,,7.00042905,,,,
,11382054.09,7.0016452125,-0.024,3981.09972041007,2.99951164747064,,1.41939191692268e-08,1.15827068134066e-05,1.29609529388449e-05,1.73823300569368e-05,48.2140617509146,1.53523683614764e-08,-1.2656283102313901e-09,1.54044483616299e-08,-4.71272909852405,568,25,5,13.4965986394558,-0.076805167652275,0.0020841790364603,4369,0,7.0005765,7.0041323,-0.024,-0.024,,7.0055625,,,,,,,,,,,,,,,,,,,,,,,7.0016452125,,,,
,11382563.17,7.5025024375,-0.024,25.1190587138863,3.00136973837459,,7.26545681970026e-07,7.38129813208101e-05,2.21013350957753e-06,7.38460621942458e-05,1.7150573900126,1.5391518939478e-08,4.0244516892548493e-11,1.53915715534656e-08,0.149812095917606,400,25,5,13.4965986394558,-0.076805167652275,0.0001148340022993,4369,0,7.501801,7.504509,-0.024,-0.024,,7.4964375,,,,,,,,,,,,,,,,,,,,,,,7.5025024375,,,,
,11382873.08,7.499751325,-0.024,199.530288909599,3.0012404227093,,1.0430997628e-07,6.24227417214064e-05,2.1481241685792e-05,6.60154711289772e-05,18.9896338231558,1.53805746411714e-08,-2.76620932836157e-11,1.53805995164054e-08,-0.103046831847848,398,25,5,13.4965986394558,-0.076805167652275,0.0002116936789662,4373,0,7.4903235,7.5083151,-0.024,-0.024,,7.5,,,,,,,,,,,,,,,,,,,,,,,7.499751325,,,,
,11383186.56,7.503513025,-0.024,1584.90027958993,3.00142800382918,,1.68678967581958e-08,1.98472841905075e-05,2.01765430573874e-05,2.83020772998269e-05,45.4713371803363,1.53834813467357e-08,-4.92338697781555e-10,1.53913578263485e-08,-1.83308988858738,528,25,5,13.4965986394558,-0.076805167652275,0.0009249068916225,4373,0,7.4801626,7.5414071,-0.024,-0.024,,7.4923625,,,,,,,,,,,,,,,,,,,,,,,7.503513025,,,,
,11383690.06,8.0013794875,-0.024,10.0,3.00137149090889,,8.79375629158401e-07,6.90430116057311e-05,1.99723687987876e-06,6.90718930299689e-05,1.65695757121984,1.54424063953007e-08,9.183257991147169e-11,1.54426794469211e-08,0.340721328856855,320,25,5,13.4965986394558,-0.076805167652275,0.0001048040915143,4369,0,8.0004244,8.0024433,-0.024,-0.024,,7.9975375,,,,,,,,,,,,,,,,,,,,,,,8.0013794875,,,,
,11383997.52,7.9998605125,-0.024,79.4333643988816,3.00135099520827,,9.87636962732103e-08,6.73576142982436e-05,9.04099933759917e-06,6.79616647307394e-05,7.64476997788252,1.53944795142562e-08,6.978562369495089e-11,1.53946376881084e-08,0.259729100713054,316,25,5,13.4965986394558,-0.076805167652275,0.0001441357871519,4369,0,7.9988074,8.0021915,-0.024,-0.024,,7.9964875,,,,,,,,,,,,,,,,,,,,,,,7.9998605125,,,,
,11384312.29,8.0130150125,-0.024,630.960391425909,3.00005862577851,,2.15059905462089e-08,3.6627061881259e-05,2.63902643564003e-05,4.51440772954135e-05,35.7732300734791,1.53969992642108e-08,-1.1856435207509301e-10,1.53974557589133e-08,-0.441196533747643,210,25,5,13.4965986394558,-0.076805167652275,0.0004375871315751,4373,0,7.9972,8.042532,-0.024,-0.024,,8.0188625,,,,,,,,,,,,,,,,,,,,,,,8.0130150125,,,,
,11384625.51,8.0024037375,-0.024,5011.89934762349,2.99872559688416,,7.2926859121766e-09,9.17411726640872e-06,1.08062916147488e-05,1.41753435965697e-05,49.6700504070926,1.53324763049751e-08,-1.59679701204278e-09,1.5415401076206e-08,-5.94562116906189,455,25,5,13.4965986394558,-0.076805167652275,0.0025730212668863,4373,0,7.9927068,8.0251617,-0.024,-0.024,,7.9945375,,,,,,,,,,,,,,,,,,,,,,,8.0024037375,,,,
,11385133.73,8.49823655,-0.024,31.6230195712954,3.00136852027881,,4.14413338149875e-07,6.42146669884221e-05,2.69044841953246e-06,6.42710041086345e-05,2.39915959183865,1.54081344252807e-08,3.1607581522575e-11,1.54081668444605e-08,0.117533922773447,496,25,5,13.4965986394558,-0.076805167652275,0.0001176016527069,4369,0,8.4969292,8.4992924,-0.024,-0.024,,8.5031375,,,,,,,,,,,,,,,,,,,,,,,8.49823655,,,,
,11385441.02,8.4986887,-0.024,251.189655172414,3.00116358324547,,3.56541528982837e-08,5.54660843563531e-05,1.94080835266361e-05,5.87635960438345e-05,19.2854024762042,1.53818202305826e-08,-3.83541570785178e-11,1.53818680480404e-08,-0.142865196715263,502,25,5,13.4965986394558,-0.076805167652275,0.0002384027854585,4369,0,8.4977846,8.499341,-0.024,-0.024,,8.5037875,,,,,,,,,,,,,,,,,,,,,,,8.4986887,,,,
,11385757.12,8.4593256625,-0.024,1995.30009319664,3.00076496165185,,1.22582403096368e-08,1.64136690761188e-05,1.78959583528015e-05,2.42832011461739e-05,47.473828612118,1.53803300696391e-08,-6.25556944369845e-10,1.53930463047993e-08,-2.32908061018713,399,25,5,13.4965986394558,-0.076805167652275,0.0011253290560298,4373,0,8.4467134,8.4718084,-0.024,-0.024,,8.47565,,,,,,,,,,,,,,,,,,,,,,,8.4593256625,,,,
,11386267.13,9.0001009625,-0.024,12.5890027958993,3.00137129787711,,8.27896321607639e-07,6.30870376642938e-05,1.18145291364342e-06,6.30980994344773e-05,1.07287259449753,1.53768425038938e-08,3.2524410545198794e-11,1.53768769009456e-08,0.121189293307955,384,25,5,13.4965986394558,-0.076805167652275,0.000106849552342,4369,0,8.9809656,9.0142374,-0.024,-0.024,,9.006025,,,,,,,,,,,,,,,,,,,,,,,9.0001009625,,,,
,11386578.2,8.99874615,-0.024,100.0,3.00133881500266,,1.26853417708014e-07,5.97129439403124e-05,7.44389630377786e-06,6.01751382732129e-05,7.10591094277601,1.53894732563114e-08,7.731775316676169e-11,1.5389667479893e-08,0.287855444557098,400,25,5,13.4965986394558,-0.076805167652275,0.0001546037246022,4369,0,8.9974146,9.0006924,-0.024,-0.024,,9.0032625,,,,,,,,,,,,,,,,,,,,,,,8.99874615,,,,
,11386893.02,8.999173275,-0.024,794.330848089469,2.99929132153899,,1.60945237233906e-08,3.23149461797546e-05,2.43754118111586e-05,4.04773572205994e-05,37.0275306103006,1.54038305044416e-08,-1.53991412120933e-10,1.54046002078786e-08,-0.572764293139358,264,25,5,13.4965986394558,-0.076805167652275,0.0005194466299836,4369,0,8.9985332,9.0000696,-0.024,-0.024,,9.0037125,,,,,,,,,,,,,,,,,,,,,,,8.999173275,,,,
,11387206.66,9.0013080875,-0.024,6309.59972041006,3.00162843652362,,1.1629852340039e-08,7.55281418400308e-06,9.34611037719076e-06,1.20164379614223e-05,51.0574977602695,1.5301337421069e-08,-2.0145817606957e-09,1.54333880448829e-08,-7.50045078506048,573,25,5,13.4965986394558,-0.076805167652275,0.0031848476360486,4369,0,8.9999113,9.0039082,-0.024,-0.024,,9.001675,,,,,,,,,,,,,,,,,,,,,,,9.0013080875,,,,
,11387893.73,9.5065388625,-0.024,39.8108108108108,3.00136658978538,,2.78287500170081e-07,5.84823638108364e-05,2.69335059972372e-06,5.85443508321346e-05,2.63684039637829,1.54001124205956e-08,4.2648377165393e-11,1.5400171474729e-08,0.158671943496285,312,25,5,13.4965986394558,-0.076805167652275,0.0001235900324345,4369,0,9.4842138,9.5226202,-0.024,-0.024,,9.5001125,,,,,,,,,,,,,,,,,,,,,,,9.5065388625,,,,
,11388206.81,9.5036417125,-0.024,316.22972972973,3.00104180430481,,2.67085960788812e-08,5.03992505117758e-05,1.73507329293619e-05,5.33022737351304e-05,18.9968282386184,1.53863512601486e-08,-5.0443322452869095e-11,1.53864339477819e-08,-0.187840448822499,316,25,5,13.4965986394558,-0.076805167652275,0.000273422732071,4369,0,9.4868288,9.5189056,-0.024,-0.024,,9.5008625,,,,,,,,,,,,,,,,,,,,,,,9.5036417125,,,,
,11388519.32,9.5001957375,-0.024,2511.90074557316,3.00145181849252,,1.07506296434987e-08,1.39223908244748e-05,1.63249796685115e-05,2.14554871174423e-05,49.5415445663457,1.53745763800088e-08,-7.929161437129201e-10,1.5395009414602e-08,-2.95231118889649,502,25,5,13.4965986394558,-0.076805167652275,0.0013741830077659,4369,0,9.4901466,9.5175753,-0.024,-0.024,,9.485775,,,,,,,,,,,,,,,,,,,,,,,9.5001957375,,,,
,11389026.9,10.006939525,-0.024,15.8490214352283,3.00137099187908,,9.03307728677768e-07,5.43151664243125e-05,1.66433036940889e-06,5.43406597243657e-05,1.75511341557456,1.53829307123644e-08,2.96137563996107e-11,1.53829592171328e-08,0.1103002537616,480,25,5,13.4965986394558,-0.076805167652275,0.0001078367936879,4369,0,10.0050688,10.0080976,-0.024,-0.024,,9.984325,,,,,,,,,,,,,,,,,,,,,,,10.006939525,,,,
,11389337.61,10.0026906875,-0.024,125.890027958993,3.00131951260894,,6.77296422967134e-08,5.4469568014215e-05,6.88877790200781e-06,5.49034525384186e-05,7.20794236603671,1.53810948386181e-08,-1.2086226788511398e-11,1.53810995872026e-08,-0.0450221294360063,500,25,5,13.4965986394558,-0.076805167652275,0.0001689599683181,4369,0,10.0014963,10.0038338,-0.024,-0.024,,9.979775,,,,,,,,,,,,,,,,,,,,,,,10.0026906875,,,,
,11389645.71,10.0006666,-0.024,1000.0,2.99807640102726,,1.63031734593794e-08,2.94526971434588e-05,2.27661232312272e-05,3.72257670975861e-05,37.7030347980988,1.54163953224756e-08,-1.98781572538271e-10,1.54176768305873e-08,-0.73874039815388,333,25,5,13.4965986394558,-0.076805167652275,0.0006221836018126,4369,0,9.9994354,10.0022001,-0.024,-0.024,,9.9777875,,,,,,,,,,,,,,,,,,,,,,,10.0006666,,,,
,11389984.46,10.0037262375,-0.024,7943.30009319665,2.99933830360841,,1.12014758877853e-08,6.34342451628385e-06,8.29815936950706e-06,1.04450219490209e-05,52.6043463253546,1.52541991997865e-08,-2.52789317188456e-09,1.54622390718559e-08,-9.40942044989771,611,5,5,13.4965986394558,-0.076805167652275,0.0039232773862439,4369,0,10.0026102,10.0052614,-0.024,-0.024,,9.97675,,,,,,,,,,,,,,,,,,,,,,,10.0037262375,,,,
,11390472.54,10.5022675875,-0.024,50.118825722274,3.00136353011628,,1.28756345526539e-07,5.19842972192117e-05,1.84070497420835e-06,5.201687564798e-05,2.02793128630116,1.54036960429465e-08,4.8944184281679594e-11,1.54037738011391e-08,0.182052784334154,400,25,5,13.4965986394558,-0.076805167652275,0.0001267385596051,4369,0,10.4926767,10.5120316,-0.024,-0.024,,10.4781375,,,,,,,,,,,,,,,,,,,,,,,10.5022675875,,,,
,11390792.49,10.507188925,-0.024,398.109972041007,3.0008488274793,,2.90968609719226e-08,4.65477109349347e-05,1.54984431375719e-05,4.9060076772981e-05,18.4156036537412,1.53853969249874e-08,-6.903849670636419e-11,1.53855518215447e-08,-0.257100155115324,398,25,5,13.4965986394558,-0.076805167652275,0.0003151350589829,4369,0,10.5034103,10.5111332,-0.024,-0.024,,10.4745125,,,,,,,,,,,,,,,,,,,,,,,10.507188925,,,,
,11391116.77,10.5023931375,-0.024,3162.30009319665,3.00186717732107,,1.0809452198329e-08,1.22482329169924e-05,1.53106575409209e-05,1.9607025371643e-05,51.3408605950055,1.53653562866595e-08,-1.00241464733743e-09,1.53980196434861e-08,-3.73260818813583,451,25,5,13.4965986394558,-0.076805167652275,0.0016874764025641,4369,0,10.5019541,10.5028038,-0.024,-0.024,,10.46835,,,,,,,,,,,,,,,,,,,,,,,10.5023931375,,,,
,11391637.39,11.0093802375,-0.024,19.952935694315,3.00137050692122,,6.67743401712289e-07,5.08291294406553e-05,8.69096429654492e-07,5.08365589738224e-05,0.979570300480982,1.53762683652854e-08,2.99308168959865e-11,1.53762974963116e-08,0.111529486790942,304,25,5,13.4965986394558,-0.076805167652275,0.0001103409063717,4369,0,11.0087929,11.0097275,-0.024,-0.024,,10.978425,,,,,,,,,,,,,,,,,,,,,,,11.0093802375,,,,
,11391954.75,11.0037998125,-0.024,158.490214352283,3.00128891477575,,5.42651584672794e-08,4.97319446092561e-05,5.86461718990444e-06,5.00765419073865e-05,6.72551832488539,1.5381330788407e-08,-1.68213802934707e-11,1.53813399865302e-08,-0.0626599691159981,316,25,5,13.4965986394558,-0.076805167652275,0.0001860463753381,4369,0,11.0018044,11.0050678,-0.024,-0.024,,10.97315,,,,,,,,,,,,,,,,,,,,,,,11.0037998125,,,,
,11392280.61,11.0015730875,-0.024,1258.90027958993,3.00031529927546,,1.52355974272248e-08,2.77084279612875e-05,2.14301746993847e-05,3.50286934916506e-05,37.7189830608084,1.53841709038432e-08,-3.87152871163857e-10,1.53890416122742e-08,-1.44158204656264,419,25,5,13.4965986394558,-0.076805167652275,0.0007639088210856,4369,0,11.0010157,11.0025234,-0.024,-0.024,,10.9707375,,,,,,,,,,,,,,,,,,,,,,,11.0015730875,,,,
,11392632.09,11.0024327125,-0.024,10000.0,2.99875322179749,,7.23962018623039e-09,5.43204752878713e-06,7.62047802282487e-06,9.35835592672983e-06,54.5178769881936,1.51902052550662e-08,-3.2060518146448504e-09,1.55248543931732e-08,-11.9179606212177,588,5,5,13.4965986394558,-0.076805167652275,0.0047985019170295,4369,0,11.0013638,11.002943,-0.024,-0.024,,10.96735,,,,,,,,,,,,,,,,,,,,,,,11.0024327125,,,,
,11393127.1,11.505230675,-0.024,63.096458527493,3.00135868063289,,1.71095445195187e-07,4.7945720596554e-05,1.9600882722948e-06,4.79857694484314e-05,2.34102819099149,1.53953276343507e-08,6.216516963810619e-11,1.53954531429678e-08,0.23135477071789,504,25,5,13.4965986394558,-0.076805167652275,0.0001332519218284,4369,0,11.5039663,11.5060444,-0.024,-0.024,,11.4756625,,,,,,,,,,,,,,,,,,,,,,,11.505230675,,,,
,11393444.82,11.5014743625,-0.024,501.189655172414,3.00054305769988,,2.86584206148905e-08,4.31264815495618e-05,1.37041287112196e-05,4.52514812418154e-05,17.6284862557167,1.53897156955772e-08,-9.14367348318623e-11,1.5389987325114e-08,-0.340414173830482,501,25,5,13.4965986394558,-0.076805167652275,0.0003691113642936,4369,0,11.5008335,11.5024958,-0.024,-0.024,,11.4725125,,,,,,,,,,,,,,,,,,,,,,,11.5014743625,,,,
,11393766.28,11.501752625,-0.024,3981.09972041007,2.99951164747064,,6.058687003667931e-09,1.11051191671427e-05,1.45487078628095e-05,1.83026930311858e-05,52.6452808830351,1.5350930334006e-08,-1.2664050612014801e-09,1.54030790395473e-08,-4.71604814169689,568,25,5,13.4965986394558,-0.076805167652275,0.0020792951250338,4369,0,11.5008364,11.5027742,-0.024,-0.024,,11.4709,,,,,,,,,,,,,,,,,,,,,,,11.501752625,,,,
,11394285.04,12.0079442125,-0.024,25.1190587138863,3.00136973837459,,4.4745312838551e-07,4.63629065858571e-05,3.68376132121848e-07,4.63643700276799e-05,0.455233613680184,1.53663760971219e-08,2.6729552772321498e-11,1.53663993449081e-08,0.0996649442775004,400,25,5,13.4965986394558,-0.076805167652275,0.0001126824174887,4369,0,12.007225,12.0088072,-0.024,-0.024,,11.9789125,,,,,,,,,,,,,,,,,,,,,,,12.0079442125,,,,
,11394603.65,12.0035173875,-0.024,199.530288909599,3.0012404227093,,3.75072166887517e-08,4.58538322044254e-05,5.17716995659047e-06,4.61451732751219e-05,6.44175356607908,1.53814730232005e-08,-2.93315808798936e-11,1.53815009899906e-08,-0.109259610652089,398,25,5,13.4965986394558,-0.076805167652275,0.0002070582685022,4369,0,12.0024633,12.0046225,-0.024,-0.024,,11.9738625,,,,,,,,,,,,,,,,,,,,,,,12.0035173875,,,,
,11394925.66,12.001527675,-0.024,1584.90027958993,3.00142800382918,,1.7013882129389e-08,2.6372143627367e-05,2.00961670127652e-05,3.31563853293363e-05,37.3082165111768,1.53824066603869e-08,-4.92422791222993e-10,1.53902863804034e-08,-1.83353077669267,528,25,5,13.4965986394558,-0.076805167652275,0.000929352541708,4369,0,12.0003052,12.0028954,-0.024,-0.024,,11.9712125,,,,,,,,,,,,,,,,,,,,,,,12.001527675,,,,
,11395445.96,12.512610925,-0.024,10.0,3.00137149090889,,5.60211684814042e-07,4.2773998736431e-05,-1.27087978240321e-06,4.27928744457009e-05,-1.70184304957291,1.54153647749897e-08,1.07429733836108e-10,1.54157391095499e-08,0.399288034248528,320,25,5,13.4965986394558,-0.076805167652275,0.0001029943549795,4369,0,12.5118628,12.5130949,-0.024,-0.024,,12.4847875,,,,,,,,,,,,,,,,,,,,,,,12.512610925,,,,
,11395768.4,12.5044842,-0.024,79.4333643988816,3.00135099520827,,8.85567273120688e-08,4.48096136156538e-05,1.86545765061581e-06,4.48484270028551e-05,2.3838895016123,1.53923380864331e-08,7.16744216961034e-11,1.53925049614995e-08,0.266795866756978,316,25,5,13.4965986394558,-0.076805167652275,0.0001414673164872,4369,0,12.50418,12.5047579,-0.024,-0.024,,12.4764,,,,,,,,,,,,,,,,,,,,,,,12.5044842,,,,
,11396089.12,12.502031925,-0.024,630.960391425909,3.00005862577851,,2.3151631453282e-08,4.03826517686079e-05,1.21557689022507e-05,4.21725180831021e-05,16.7525631874125,1.53952672951748e-08,-1.19020333800535e-10,1.53957273595546e-08,-0.442943069289583,210,25,5,13.4965986394558,-0.076805167652275,0.0004361448966463,4369,0,12.5015802,12.5025301,-0.024,-0.024,,12.4732,,,,,,,,,,,,,,,,,,,,,,,12.502031925,,,,
,11396409.2,12.5021615,-0.024,5011.89934762349,2.99872559688416,,7.203467536372811e-09,1.0223294384536e-05,1.39591811585088e-05,1.73024416395188e-05,53.7820476916117,1.5331250362451e-08,-1.59718540432793e-09,1.54142219684275e-08,-5.94752911135492,455,25,5,13.4965986394558,-0.076805167652275,0.0025749075560721,4369,0,12.5016298,12.5024557,-0.024,-0.024,,12.470975,,,,,,,,,,,,,,,,,,,,,,,12.5021615,,,,
,11396926.75,13.006146425,-0.024,31.6230195712954,3.00136852027881,,2.70390122367695e-07,4.30755491060278e-05,3.85734321448448e-07,4.30772761644995e-05,0.513060387348838,1.53826485544771e-08,4.33731146374614e-11,1.53827097020528e-08,0.161551492163974,496,25,5,13.4965986394558,-0.076805167652275,0.0001155603946776,4369,0,13.0047445,13.0071468,-0.024,-0.024,,12.9823,,,,,,,,,,,,,,,,,,,,,,,13.006146425,,,,
,11397246.81,13.002523775,-0.024,251.189655172414,3.00116358324547,,3.20754276848169e-08,4.24063382720937e-05,4.54854335809592e-06,4.26495811506715e-05,6.12219188310416,1.5381491164771e-08,-3.9031667876085695e-11,1.53815406875588e-08,-0.145391952740908,502,25,5,13.4965986394558,-0.076805167652275,0.0002349755403053,4369,0,13.0014706,13.0037127,-0.024,-0.024,,12.97835,,,,,,,,,,,,,,,,,,,,,,,13.002523775,,,,
,11397571.05,13.00100315,-0.024,1995.30009319664,3.00076496165185,,1.03987936818628e-08,2.53235536528564e-05,1.88413858396841e-05,3.15639064434196e-05,36.6502114698419,1.53798098375993e-08,-6.25344272976617e-10,1.53925178609759e-08,-2.3283683304636,399,25,5,13.4965986394558,-0.076805167652275,0.0011334284560698,4369,0,12.9997425,13.0021439,-0.024,-0.024,,12.9767625,,,,,,,,,,,,,,,,,,,,,,,13.00100315,,,,
,11398086.25,13.510002725,-0.024,12.5890027958993,3.00137129787711,,7.68502868977742e-07,4.32720517492034e-05,2.48555873368995e-07,4.32727655992534e-05,0.329104937727594,1.54293164340866e-08,4.25171498024967e-11,1.54293750142772e-08,0.157884316203321,384,25,5,13.4965986394558,-0.076805167652275,0.0001048506323036,4369,0,13.5088997,13.511631,-0.024,-0.024,,13.4862125,,,,,,,,,,,,,,,,,,,,,,,13.510002725,,,,
,11398405.07,13.5038924,-0.024,100.0,3.00133881500266,,6.17739814300748e-08,4.14345077382165e-05,1.57652706500047e-06,4.14644892539991e-05,2.17897594114729,1.53914135429759e-08,8.86406369677266e-11,1.53916687858538e-08,0.329968279353739,400,25,5,13.4965986394558,-0.076805167652275,0.0001522300619719,4369,0,13.5026407,13.50494,-0.024,-0.024,,13.481025,,,,,,,,,,,,,,,,,,,,,,,13.5038924,,,,
,11398724.18,13.5017103875,-0.024,794.330848089469,2.99929132153899,,1.33576813190573e-08,3.77594917769857e-05,1.08523664967133e-05,3.92880780623746e-05,16.0350554661778,1.5402893260424e-08,-1.53569680324371e-10,1.54036588003866e-08,-0.571230538462942,264,25,5,13.4965986394558,-0.076805167652275,0.0005204101453867,4369,0,13.5011568,13.502141,-0.024,-0.024,,13.478275,,,,,,,,,,,,,,,,,,,,,,,13.5017103875,,,,
,11399046.02,13.5021356375,-0.024,6309.59972041006,3.00162843652362,,5.81859554756289e-09,9.61153886631844e-06,1.34412828431849e-05,1.65242174958225e-05,54.4323504164528,1.53003760655235e-08,-2.01385693230154e-09,1.54323403115089e-08,-7.49824864009702,573,25,5,13.4965986394558,-0.076805167652275,0.0031905928779472,4369,0,13.5013771,13.5031834,-0.024,-0.024,,13.4753625,,,,,,,,,,,,,,,,,,,,,,,13.5021356375,,,,
,11399561.45,14.0060763375,-0.024,39.8108108108108,3.00136658978538,,1.95598244373106e-07,3.98077588762073e-05,3.87410682411673e-07,3.98096439796076e-05,0.557587187234902,1.53862607236405e-08,4.26316605446068e-11,1.53863197846114e-08,0.158752540074194,312,25,5,13.4965986394558,-0.076805167652275,0.0001202562460982,4369,0,14.0051746,14.006916,-0.024,-0.024,,13.9798125,,,,,,,,,,,,,,,,,,,,,,,14.0060763375,,,,
,11399883.43,14.0028118875,-0.024,316.22972972973,3.00104180430481,,5.06319644091646e-08,3.9457727791934e-05,4.05044013537026e-06,3.96650771812255e-05,5.86103385470397,1.53851022042495e-08,-5.1529567310732094e-11,1.53851884984069e-08,-0.191900947286058,316,25,5,13.4965986394558,-0.076805167652275,0.0002696373241696,4369,0,14.0023718,14.0033092,-0.024,-0.024,,13.97575,,,,,,,,,,,,,,,,,,,,,,,14.0028118875,,,,
,11400205.18,14.0015503125,-0.024,2511.90074557316,3.00145181849252,,1.02189607409509e-08,2.43392723325389e-05,1.76611676260387e-05,3.00718642520302e-05,35.9655511577136,1.53737852209169e-08,-7.924971921992151e-10,1.53941977322148e-08,-2.95090562167985,502,25,5,13.4965986394558,-0.076805167652275,0.0013878967141649,4369,0,14.0012674,14.0018864,-0.024,-0.024,,13.9739875,,,,,,,,,,,,,,,,,,,,,,,14.0015503125,,,,
,11400724.29,14.5093645875,-0.024,15.8490214352283,3.00137099187908,,5.96235960242547e-07,3.87327918870749e-05,-2.35475172860204e-07,3.87335076635784e-05,-0.348324164434246,1.53841132587912e-08,4.3864482292856394e-11,1.53841757937213e-08,0.163366120159432,480,25,5,13.4965986394558,-0.076805167652275,0.000106966384825,4369,0,14.5088873,14.5097952,-0.024,-0.024,,14.4835875,,,,,,,,,,,,,,,,,,,,,,,14.5093645875,,,,
,11401044.26,14.5038461875,-0.024,125.890027958993,3.00131951260894,,4.62328588023164e-08,3.86114330276116e-05,1.49252417123852e-06,3.8640269005889e-05,2.21366509150863,1.53806452311485e-08,-1.06123363063828e-11,1.53806488922976e-08,-0.0395329308686883,500,25,5,13.4965986394558,-0.076805167652275,0.0001674163627253,4369,0,14.5031462,14.5056772,-0.024,-0.024,,14.47725,,,,,,,,,,,,,,,,,,,,,,,14.5038461875,,,,
,11401364.19,14.501793025,-0.024,1000.0,2.99807640102726,,1.17361637874996e-08,3.5444265810912e-05,9.80179418957229e-06,3.67745992256791e-05,15.4583061947527,1.5416239097577e-08,-1.98967594573138e-10,1.54175230182203e-08,-0.739439135429564,333,25,5,13.4965986394558,-0.076805167652275,0.0006246517268219,4369,0,14.5012722,14.5021772,-0.024,-0.024,,14.4748625,,,,,,,,,,,,,,,,,,,,,,,14.501793025,,,,
,11401716.93,14.5020515875,-0.024,7943.30009319665,2.99933830360841,,1.1561439686446e-08,9.09776500183527e-06,1.29294204634687e-05,1.58094668331915e-05,54.8679292510347,1.52546523060696e-08,-2.5261949726763e-09,1.54624085452121e-08,-9.40293796443513,611,5,5,13.4965986394558,-0.076805167652275,0.0039318646785655,4369,0,14.5015745,14.5023012,-0.024,-0.024,,14.471825,,,,,,,,,,,,,,,,,,,,,,,14.5020515875,,,,
,11402200.22,15.007783525,-0.024,50.118825722274,3.00136353011628,,3.84099782619366e-07,3.67764360878963e-05,1.23132183733714e-06,3.67970434246316e-05,1.91761920980669,1.53797161256227e-08,4.77867778680474e-11,1.53797903653099e-08,0.178024864373238,400,25,5,13.4965986394558,-0.076805167652275,0.0001257177924162,4369,0,15.0072584,15.0081253,-0.024,-0.024,,14.9735625,,,,,,,,,,,,,,,,,,,,,,,15.007783525,,,,
,11402517.02,15.0035705375,-0.024,398.109972041007,3.0008488274793,,3.16014746811872e-08,3.70088484140931e-05,3.64044400998863e-06,3.71874668877457e-05,5.61793235395546,1.53852717934216e-08,-6.86886465066954e-11,1.53854251253455e-08,-0.255799406731796,398,25,5,13.4965986394558,-0.076805167652275,0.0003121494281254,4369,0,15.003293,15.004117,-0.024,-0.024,,14.9692625,,,,,,,,,,,,,,,,,,,,,,,15.0035705375,,,,
,11402842.91,15.0019095125,-0.024,3162.30009319665,3.00186717732107,,7.7853049664749e-09,2.33034003488256e-05,1.65329120277966e-05,2.85724631058736e-05,35.3543098272245,1.53649780402016e-08,-1.0021006372811302e-09,1.53976217599705e-08,-3.73153383788218,451,25,5,13.4965986394558,-0.076805167652275,0.0017071156056432,4369,0,15.0010834,15.0024281,-0.024,-0.024,,14.9675,,,,,,,,,,,,,,,,,,,,,,,15.0019095125,,,,
,11403358.04,15.510437375,-0.024,19.952935694315,3.00137050692122,,3.32691275906128e-07,3.55885986641633e-05,3.19827166189784e-07,3.55900357445046e-05,0.514891122199387,1.53764583082004e-08,1.54877336450194e-11,1.53764661081056e-08,0.0577103943057377,304,25,5,13.4965986394558,-0.076805167652275,0.0001091183164696,4369,0,15.5086346,15.5125332,-0.024,-0.024,,15.4787375,,,,,,,,,,,,,,,,,,,,,,,15.510437375,,,,
,11403676.88,15.5042629125,-0.024,158.490214352283,3.00128891477575,,3.58505423905882e-08,3.62523414349586e-05,1.33242302377526e-06,3.62768191912012e-05,2.10490866464922,1.53801588662e-08,-1.7480154314323598e-11,1.53801687996376e-08,-0.0651188745789,316,25,5,13.4965986394558,-0.076805167652275,0.0001840293818816,4369,0,15.5024624,15.5053825,-0.024,-0.024,,15.4725625,,,,,,,,,,,,,,,,,,,,,,,15.5042629125,,,,
,11403997.77,15.501613275,-0.024,1258.90027958993,3.00031529927546,,1.85348656607254e-08,3.34857912477357e-05,8.96119977927839e-06,3.46641214654442e-05,14.9819732908018,1.53841298793309e-08,-3.86401267006186e-10,1.53889817104078e-08,-1.43878842557626,419,25,5,13.4965986394558,-0.076805167652275,0.0007675110606848,4369,0,15.500452,15.5032406,-0.024,-0.024,,15.470275,,,,,,,,,,,,,,,,,,,,,,,15.501613275,,,,
,11404350.14,15.50243795,-0.024,10000.0,2.99875322179749,,1.07489330318024e-08,8.70170469130149e-06,1.24020282383705e-05,1.51502464983233e-05,54.9451329853387,1.51900885033915e-08,-3.2033449621890603e-09,1.55241813854274e-08,-11.9082746552596,588,5,5,13.4965986394558,-0.076805167652275,0.0048152118843836,4369,0,15.5016346,15.5037756,-0.024,-0.024,,15.4668375,,,,,,,,,,,,,,,,,,,,,,,15.50243795,,,,
,11404836.3,16.0072953875,-0.024,63.096458527493,3.00135868063289,,1.67588243077e-07,3.50705426813744e-05,6.77015041249427e-07,3.50770767500968e-05,1.10592206871612,1.53924276418695e-08,6.540489690313329e-11,1.53925665991974e-08,0.243457502985543,504,25,5,13.4965986394558,-0.076805167652275,0.0001324260990287,4369,0,16.0070858,16.0074787,-0.024,-0.024,,15.9731125,,,,,,,,,,,,,,,,,,,,,,,16.0072953875,,,,
,11405150.94,16.0024717,-0.024,501.189655172414,3.00054305769988,,1.71012680175322e-08,3.46943540282945e-05,3.32957101164522e-06,3.48537550998773e-05,5.48181175317773,1.53900213766611e-08,-9.09304707566716e-11,1.53902900013157e-08,-0.338522699372959,501,25,5,13.4965986394558,-0.076805167652275,0.000366082402614,4369,0,16.0019379,16.0029278,-0.024,-0.024,,15.9693375,,,,,,,,,,,,,,,,,,,,,,,16.0024717,,,,
,11405469.67,16.002747075,-0.024,3981.09972041007,2.99951164747064,,8.3970735831432e-09,2.23758324261871e-05,1.55546512194265e-05,2.72511477065244e-05,34.8052528941092,1.53508914394378e-08,-1.26570541899819e-09,1.54029827693562e-08,-4.7134663296344,568,25,5,13.4965986394558,-0.076805167652275,0.0021051936849898,4369,0,16.0024071,16.0030251,-0.024,-0.024,,15.965875,,,,,,,,,,,,,,,,,,,,,,,16.002747075,,,,
,11405986.29,16.5095303125,-0.024,25.1190587138863,3.00137076925091,,4.05266374082783e-07,3.41818981023e-05,-1.91582013600871e-07,3.41824349855881e-05,-0.321126867756846,1.53722638766057e-08,3.0396282656913e-11,1.53722939285585e-08,0.11329342595959,400,25,5,13.4965986394558,-0.076805167652275,0.0001121301883704,4369,0,16.5085545,16.5110588,-0.024,-0.024,,16.4761375,,,,,,,,,,,,,,,,,,,,,,,16.5095303125,,,,
,11406308.12,16.5042991625,-0.024,199.530288909599,3.00124150744186,,4.17205543157185e-08,3.41162749640317e-05,1.25637560178273e-06,3.4139400947793e-05,2.10903753600492,1.53801020857553e-08,-2.80253499572976e-11,1.53801276193826e-08,-0.104403240354429,398,25,5,13.4965986394558,-0.076805167652275,0.0002058661355067,4369,0,16.5031013,16.5056038,-0.024,-0.024,,16.4707625,,,,,,,,,,,,,,,,,,,,,,,16.5042991625,,,,
,11406629.59,16.5023963125,-0.024,1584.90027958993,3.00142909545961,,1.06434433202836e-08,3.16362975468494e-05,8.23388700193657e-06,3.26902465214542e-05,14.5885492393373,1.53832847156294e-08,-4.9240945815813e-10,1.53911635595429e-08,-1.83337658407748,528,25,5,13.4965986394558,-0.076805167652275,0.0009348096333513,4369,0,16.5014076,16.5028648,-0.024,-0.024,,16.468125,,,,,,,,,,,,,,,,,,,,,,,16.5023963125,,,,
,11407147.28,17.01476145,-0.024,10.0,3.00136610506183,,6.5104879883555e-07,3.13388489476932e-05,-4.78835575783737e-07,3.13425068696645e-05,-0.875371106782325,1.53787091144109e-08,8.18080192770619e-11,1.53789267043472e-08,0.304785660997651,320,25,5,13.4965986394558,-0.076805167652275,0.0001026146150876,4369,0,17.0109959,17.0191441,-0.024,-0.024,,16.9809375,,,,,,,,,,,,,,,,,,,,,,,17.01476145,,,,
,11407462.48,17.0057559,-0.024,79.4333643988816,3.00134578547051,,9.08895831045252e-08,3.33236034630351e-05,5.67342090086248e-07,3.33284326785522e-05,0.975379722685176,1.53924230160317e-08,7.03910570911088e-11,1.53925839677873e-08,0.262017381397489,316,25,5,13.4965986394558,-0.076805167652275,0.0001408975867391,4369,0,17.0053101,17.0060539,-0.024,-0.024,,16.9738125,,,,,,,,,,,,,,,,,,,,,,,17.0057559,,,,
,11407782.06,17.0029919125,-0.024,630.960391425909,3.00005346991405,,2.35561906216579e-08,3.27658920192981e-05,3.00933461694602e-06,3.29037957484703e-05,5.24752399961723,1.53955630217511e-08,-1.18078851834363e-10,1.5396015827868e-08,-0.439430971058186,210,25,5,13.4965986394558,-0.076805167652275,0.000433665859236,4369,0,17.0026512,17.0035248,-0.024,-0.024,,16.970375,,,,,,,,,,,,,,,,,,,,,,,17.0029919125,,,,
,11408104.08,17.001938575,-0.024,5011.89934762349,2.99872072252701,,7.07600068707926e-09,2.14215870721589e-05,1.45565281705348e-05,2.58993610938505e-05,34.1971321720859,1.53315315243356e-08,-1.59606553294218e-09,1.54143856208135e-08,-5.94328062935216,455,25,5,13.4965986394558,-0.076805167652275,0.0026067885082183,4369,0,17.0016212,17.0025826,-0.024,-0.024,,16.9677625,,,,,,,,,,,,,,,,,,,,,,,17.001938575,,,,
,11408653.79,18.0071566125,-0.024,31.6230195712954,3.00133287468172,,2.86221676913314e-07,3.08685192248047e-05,-1.1234655889357e-07,3.08687236678394e-05,-0.208528151257553,1.53797493817339e-08,3.78018120930304e-11,1.53797958381099e-08,0.140826737522575,496,25,5,13.4965986394558,-0.076805167652275,0.000115593343909,4369,0,18.0067463,18.0075989,-0.024,-0.024,,17.980925,,,,,,,,,,,,,,,,,,,,,,,18.0071566125,,,,
,11408975.15,18.0032200875,-0.024,251.189655172414,3.00112813235858,,3.27857023015859e-08,3.12825313605992e-05,9.27788580423209e-07,3.1296286680321e-05,1.69880087989652,1.53826039196766e-08,-3.85657513333949e-11,1.53826522637296e-08,-0.143646041143086,502,25,5,13.4965986394558,-0.076805167652275,0.0002330332421864,4369,0,18.0026512,18.0038395,-0.024,-0.024,,17.9775875,,,,,,,,,,,,,,,,,,,,,,,18.0032200875,,,,
,11409294.24,18.0016777625,-0.024,1995.30009319664,3.00072988062336,,1.04950799029496e-08,2.96463848196089e-05,6.5720780093469e-06,3.03661051541563e-05,12.4993234456979,1.53802242569104e-08,-6.24545422437926e-10,1.53928995052116e-08,-2.32533461798158,399,25,5,13.4965986394558,-0.076805167652275,0.0011403532449131,4369,0,18.0013618,18.0022831,-0.024,-0.024,,17.9752375,,,,,,,,,,,,,,,,,,,,,,,18.0016777625,,,,
,11409846.38,19.0091957875,-0.024,12.5890027958993,3.00128045131711,,1.0488548178712e-06,2.8946814591257e-05,-5.05337208687173e-07,2.89512252016231e-05,-1.00013590116612,1.54411507449745e-08,2.20077048872087e-11,1.54411664283531e-08,0.0816615143400464,384,25,5,13.4965986394558,-0.076805167652275,0.0001044833856619,4369,0,19.0081081,19.0113392,-0.024,-0.024,,18.986,,,,,,,,,,,,,,,,,,,,,,,19.0091957875,,,,
,11410161.41,19.0042252625,-0.024,100.0,3.00124845855492,,6.15876422039537e-08,2.99108639426687e-05,1.52953744215e-07,2.99112550162094e-05,0.292988114100424,1.53947800144323e-08,8.780920137650549e-11,1.53950304367549e-08,0.326801817084826,400,25,5,13.4965986394558,-0.076805167652275,0.0001513700870323,4369,0,19.0037518,19.0045624,-0.024,-0.024,,18.9811,,,,,,,,,,,,,,,,,,,,,,,19.0042252625,,,,
,11410481.8,19.001746875,-0.024,794.330848089469,2.99920132455463,,1.08066992065675e-08,2.95622796095262e-05,2.05231506404949e-06,2.96334333622335e-05,3.9712980932622,1.54031838597452e-08,-1.53120975182354e-10,1.54039449184342e-08,-0.569550862913331,264,25,5,13.4965986394558,-0.076805167652275,0.0005168256683947,4369,0,19.0012283,19.0025043,-0.024,-0.024,,18.979175,,,,,,,,,,,,,,,,,,,,,,,19.001746875,,,,
,11410800.37,19.0018654,-0.024,6309.59972041006,3.00154546764971,,5.74152478667435e-09,2.28335452832148e-05,1.17233330066768e-05,2.56672422941394e-05,27.177137507852,1.53000881680342e-08,-2.0112975417737503e-09,1.54317210884323e-08,-7.48896673661136,573,25,5,13.4965986394558,-0.076805167652275,0.0032351995819217,4369,0,19.0014839,19.0030861,-0.024,-0.024,,18.9772,,,,,,,,,,,,,,,,,,,,,,,19.0018654,,,,
,11411384.76,20.00552915,-0.024,39.8108108108108,3.00119587843657,,1.79859753485952e-07,2.79585487650436e-05,2.63626713277275e-07,2.79597916317571e-05,0.540237282580898,1.53785252862586e-08,4.6424720323749e-11,1.53785953596143e-08,0.172964078804644,312,25,5,13.4965986394558,-0.076805167652275,0.0001198946494049,4369,0,20.0043507,20.0064144,-0.024,-0.024,,19.981225,,,,,,,,,,,,,,,,,,,,,,,20.00552915,,,,
,11411703.11,20.001935725,-0.024,316.22972972973,3.00087131013259,,3.15345694782422e-08,2.83383764154808e-05,5.76521620095022e-07,2.83442402446055e-05,1.16547606944719,1.5384448728723e-08,-5.126314843706989e-11,1.53845341364987e-08,-0.190916894798477,316,25,5,13.4965986394558,-0.076805167652275,0.00026712317269,4369,0,20.0013237,20.0036449,-0.024,-0.024,,19.97775,,,,,,,,,,,,,,,,,,,,,,,20.001935725,,,,
,11412019.45,20.0011842125,-0.024,2511.90074557316,3.00128378971043,,1.38410888558049e-08,2.74825681530868e-05,4.4197961756471e-06,2.78356992102466e-05,9.13618158840831,1.5373652677708e-08,-7.91683891745585e-10,1.53940235169123e-08,-2.94790796843051,502,25,5,13.4965986394558,-0.076805167652275,0.0013964377850493,4369,0,19.9997005,20.0025368,-0.024,-0.024,,19.9763125,,,,,,,,,,,,,,,,,,,,,,,20.0011842125,,,,
,11412567.26,21.012881275,-0.024,15.8490214352283,3.00109238442274,,3.67277736884068e-07,2.67947948005417e-05,-1.28642877660697e-06,2.6825658004985e-05,-2.74868260145803,1.54046318893294e-08,1.5118354653000798e-11,1.54046393080264e-08,0.0562309857784943,480,25,5,13.4965986394558,-0.076805167652275,0.0001061212370396,4369,0,21.0104027,21.0154953,-0.024,-0.024,,20.9793125,,,,,,,,,,,,,,,,,,,,,,,21.012881275,,,,
,11412889.26,21.0057966625,-0.024,125.890027958993,3.00104164751821,,5.51472374492745e-08,2.72254007147357e-05,2.31980662247819e-07,2.72263890206834e-05,0.488190839154061,1.53821927126714e-08,-9.368848275524939e-12,1.53821955658183e-08,-0.0348971963058489,500,25,5,13.4965986394558,-0.076805167652275,0.0001655200685597,4369,0,21.0049667,21.0071125,-0.024,-0.024,,20.9726125,,,,,,,,,,,,,,,,,,,,,,,21.0057966625,,,,
,11413207.26,21.0031292375,-0.024,1000.0,3.0019637782355,,1.8928067360832e-08,2.69933412425351e-05,1.30405607628945e-06,2.70248225468005e-05,2.76582521396142,1.54156243654879e-08,-1.98369954080206e-10,1.5416900635877e-08,-0.737247716882678,333,25,5,13.4965986394558,-0.076805167652275,0.0006206606151167,4369,0,21.000082,21.0049038,-0.024,-0.024,,20.9694125,,,,,,,,,,,,,,,,,,,,,,,21.0031292375,,,,
,11413552.86,21.0027015125,-0.024,7943.30009319665,2.99909464654001,,1.63535373366594e-08,2.34598727074359e-05,8.39359753122746e-06,2.49162217634481e-05,19.6864625960971,1.52544358993549e-08,-2.5195863269097603e-09,1.54611167082549e-08,-9.37890773412926,611,5,5,13.4965986394558,-0.076805167652275,0.0039910934835312,4369,0,21.0015564,21.0053043,-0.024,-0.024,,20.9665,,,,,,,,,,,,,,,,,,,,,,,21.0027015125,,,,
,11414067.21,22.012746075,-0.024,50.118825722274,3.00095083839238,,2.12389683312197e-07,2.53855326994001e-05,2.69215985507481e-07,2.53869601898133e-05,0.607604405934163,1.53854063617961e-08,4.8654163539512496e-11,1.53854832925464e-08,0.181189165129762,400,25,5,13.4965986394558,-0.076805167652275,0.0001247701725211,4369,0,22.0105495,22.0144939,-0.024,-0.024,,21.96675,,,,,,,,,,,,,,,,,,,,,,,22.012746075,,,,
,11414386.61,22.0059426125,-0.024,398.109972041007,3.00043707510083,,2.50179004606162e-08,2.59020454548513e-05,3.64346696887372e-07,2.59046078383888e-05,0.805888144590471,1.53850165709576e-08,-6.83407256315348e-11,1.53851683560311e-08,-0.254507973769364,398,25,5,13.4965986394558,-0.076805167652275,0.0003094439485218,4369,0,22.0054665,22.0066605,-0.024,-0.024,,21.959775,,,,,,,,,,,,,,,,,,,,,,,22.0059426125,,,,
,11414706.09,22.0038561875,-0.024,3162.30009319665,3.00146420899818,,7.21275137681274e-09,2.53980957662595e-05,2.7076300480689e-06,2.55420149759038e-05,6.08518196585611,1.53639356412201e-08,-9.999837409394702e-10,1.53964439358475e-08,-3.72392525697524,451,25,5,13.4965986394558,-0.076805167652275,0.0017182695414673,4369,0,22.0032806,22.0047112,-0.024,-0.024,,21.9565,,,,,,,,,,,,,,,,,,,,,,,22.0038561875,,,,
,11414911.52,22.00320815,-0.024,10000.0,2.99841545537872,,1.20377963362689e-08,2.30501265589246e-05,7.30779776088199e-06,2.41808238589258e-05,17.5906651777567,1.51926345879823e-08,-3.1920760030276402e-09,1.55243516751284e-08,-11.8656403262583,588,5,5,13.4965986394558,-0.076805167652275,0.0048852883993882,4369,0,22.0025177,22.004034,-0.024,-0.024,,21.953575,,,,,,,,,,,,,,,,,,,,,,,22.00320815,,,,