File: Hello.csv
Comment,Time Stamp (sec),Temperature (K),Magnetic Field (Oe),Moment (emu),M. Std. Err. (emu),Transport Action,Averaging Time (sec),Frequency (Hz),Peak Amplitude (mm),Center Position (mm),Lockin Signal' (V),Lockin Signal (V),Range,M. Quad. Signal (emu),AC Moment (emu),AC M. Std Err. (emu),AC Phase (deg),AC Phase Std. Err. (deg),AC Susceptibility (emu/Oe),AC Suscept. Std Err. (emu/Oe),AC X' (emu/Oe),AC X' Std Err. (emu/Oe),AC X'' (emu/Oe),AC X'' Std Err. (emu/Oe),AC Drive (Oe),AC Frequency (Hz),AC Averaging Time (sec),AC Cycles,AC Range,AC Measure Type,AC Signal' (V),AC Signal'' (V),AC Trim Coil Ratio,AC Trim Coil Phase,Min. Temperature (K),Max. Temperature (K),Min. Field (Oe),Max. Field (Oe),Mass (grams),Motor Lag (deg),Pressure (Torr),Measure Count,Measurement Number,SQUID Status (code),Motor Status (code),Measure Status (code),Motor Current (amps),Motor Temp. (C),Temp. Status (code),Field Status (code),Chamber Status (code),Chamber Temp (K),Redirection State,Average Temp (K),Rotation Angle (deg),Rotator state,DC Moment Fixed Ctr (emu),DC Moment Err Fixed Ctr (emu),DC Moment Free Ctr (emu),DC Moment Err Free Ctr (emu),DC Fixed Fit,DC Free Fit,DC Calculated Center (mm),DC Calculated Center Err (mm),DC Scan Length (mm),DC Scan Time (s),DC Number of Points,DC Squid Drift,DC Min V (V),DC Max V (V),DC Scans per Measure,Map 01,Map 02,Map 03,Map 04,Map 05,Map 06,Map 07,Map 08,Map 09,Map 10,Map 11,Map 12,Map 13,Map 14,Map 15,Map 16
,3820007738.85604,2.00073325634003,0.401916682720184,,,6,,,,36.9416033524933,,,10,,,,,,,,,,,,,,,,,,,,,,1.99881994724274,2.00103378295898,0.401916682720184,0.401916682720184,,,2.3030641078949,,1,0,0,0,0.0220489501953125,29.8142719268799,1,1,1,2.00052952766418,0,2.0000364681085,,,-0.0006210641350132,1.79290406767068e-05,-0.0006273162626808,1.7937094982531e-05,0.859790205955505,0.973173320293427,36.423282623291,0.0001123895490309,30,4,200,-0.0001815896830521,-0.0755929574370384,0.225600957870483,3,,,,,,,,,,,,,,,,
,3820007833.60354,2.00089812278748,1999.60852050781,,,6,,,,36.9416033524933,,,100,,,,,,,,,,,,,,,,,,,,,,1.99903929233551,2.000896692276,1999.60852050781,1999.60852050781,,,2.31040740013123,,1,0,0,0,0.0201416015625,29.3255138397217,1,1,1,2.00089955329895,0,1.99997016787529,,,0.0155036464866211,0.0007755054518376,0.0156614799787219,0.0007758627320503,0.857086598873138,0.963969886302948,36.4205093383789,0.138979077339172,30,4,200,0.0431117303669453,-4.86384201049805,4.85619211196899,3,,,,,,,,,,,,,,,,
,3820007920.26149,2.00074446201324,4000.4228515625,,,6,,,,36.9416033524933,,,100,,,,,,,,,,,,,,,,,,,,,,1.99889409542084,2.00103449821472,4000.4228515625,4000.4228515625,,,2.31338024139404,,1,0,0,0,0.023345947265625,29.3255138397217,1,1,1,2.00050234794617,0,2.00004757302148,,,0.0557057167196851,0.0016088133212091,0.056267555935964,0.0016095465974378,0.856841325759888,0.960669815540314,36.4229736328125,0.0,30,4,200,0.0029608490876853,-2.36878228187561,0.389595180749893,3,,,,,,,,,,,,,,,,
,3820008006.9309,2.00060093402863,5999.775390625,,,6,,,,36.9416033524933,,,100,,,,,,,,,,,,,,,,,,,,,,1.99895942211151,2.00090146064758,5999.775390625,5999.775390625,,,2.31683087348938,,1,0,0,0,0.022735595703125,30.3030319213867,1,1,1,2.00030040740967,0,1.99996565889429,,,0.0813160691558344,0.0023476672741104,0.0821442347964828,0.002348737353983,0.859156250953674,0.973894596099854,36.4203109741211,0.0,30,4,200,0.0015422524884343,-3.38578271865845,0.562076568603516,3,,,,,,,,,,,,,,,,
,3820008093.39536,2.00073409080505,8000.2607421875,,,6,,,,36.9416033524933,,,100,,,,,,,,,,,,,,,,,,,,,,1.99868106842041,2.0008180141449,8000.2607421875,8000.2607421875,,,2.32119178771973,,1,0,0,0,0.0179290771484375,29.8142719268799,1,1,1,2.00070190429687,0,1.99997083346049,,,0.0992496025540492,0.002865446381833,0.100261579580484,0.0028667584817366,0.859102427959442,0.973963618278503,36.4200325012207,0.0,30,4,200,0.0017356346361339,-4.12986183166504,0.679263830184937,3,,,,,,,,,,,,,,,,
,3820008180.01465,2.00066161155701,9999.9541015625,,,6,,,,36.9416033524933,,,100,,,,,,,,,,,,,,,,,,,,,,1.99867141246796,2.00086998939514,9999.9541015625,9999.9541015625,,,2.32087540626526,,1,0,0,0,0.0228118896484375,29.8142719268799,1,1,1,2.00048327445984,0,1.99999144342211,,,0.11269543667078,0.0032536376595886,0.113844798852346,0.0032551335662717,0.859110534191132,0.974034130573273,36.4200210571289,,30,4,200,0.0019590300507843,-4.68753576278687,0.778196811676025,3,,,,,,,,,,,,,,,,
,3820008271.40069,2.00061810016632,11999.6240234375,,,6,,,,36.9416033524933,,,1000,,,,,,,,,,,,,,,,,,,,,,1.99869334697723,2.0011134147644,11999.6240234375,11999.6240234375,,,2.32404756546021,,1,0,0,0,0.021209716796875,28.8367557525635,1,1,1,2.00045824050903,0,1.99997845377241,,,0.122632771562208,0.0035405232496312,0.123882462781486,0.0035421322688938,0.859140992164612,0.974089741706848,36.420093536377,0.0,30,4,200,0.0001975102204596,-4.87807559967041,4.90609550476074,3,,,,,,,,,,,,,,,,
,3820008363.30391,2.00096940994263,14000.291015625,,,6,,,,36.9416033524933,,,1000,,,,,,,,,,,,,,,,,,,,,,1.99885308742523,2.00135231018066,14000.291015625,14000.291015625,,,2.32422876358032,,1,0,0,0,0.0196075439453125,29.3255138397217,1,1,1,2.00076699256897,0,2.00001457759312,,,0.130025908062469,0.003754007482644,0.13135219037234,0.0037557073693053,0.859076023101807,0.974160194396973,36.4197807312012,6.03488063812256,30,4,200,0.0002252824924653,-0.541367173194885,0.0889552012085915,3,,,,,,,,,,,,,,,,
,3820008449.33252,2.00056767463684,16000.1328125,,,6,,,,36.9416033524933,,,1000,,,,,,,,,,,,,,,,,,,,,,1.99871098995209,2.00098872184753,16000.1328125,16000.1328125,,,2.32597398757935,,1,0,0,0,0.0,29.8142719268799,1,1,1,2.00014662742615,0,2.00009592374166,,,0.13553295118973,0.0039130185173207,0.136916524458623,0.0039148002482635,0.859044373035431,0.974202811717987,36.4196281433105,6.03486776351929,30,4,200,0.0002322598302271,-0.564249575138092,0.0924655422568321,3,,,,,,,,,,,,,,,,
,3820008536.6911,2.00080323219299,18000.458984375,,,6,,,,36.9416033524933,,,1000,,,,,,,,,,,,,,,,,,,,,,1.99864625930786,2.00088763237,18000.458984375,18000.458984375,,,2.32658910751343,,1,0,0,0,0.0201416015625,29.3255138397217,1,1,1,2.00088667869568,0,2.00002307976995,,,0.139679022898637,0.0040327421846596,0.141106231119485,0.0040345915570979,0.859010219573975,0.974246263504028,36.4194221496582,0.0,30,4,200,0.0002444560814183,-0.581432342529297,0.0955790504813194,3,,,,,,,,,,,,,,,,
,3820008623.05917,2.00119566917419,20000.154296875,,,6,,,,36.9416033524933,,,1000,,,,,,,,,,,,,,,,,,,,,,1.99835884571075,2.00125932693481,20000.154296875,20000.154296875,,,2.32755470275879,,1,0,0,0,0.022125244140625,29.8142719268799,1,1,1,2.00113201141357,0,2.00003846927925,,,0.142839354526321,0.0041240149946564,0.144299127229787,0.0041258795157891,0.858957409858704,0.974276125431061,36.4192237854004,0.0,30,4,200,0.0002532445942051,-0.594159781932831,0.0977683663368225,3,,,,,,,,,,,,,,,,
,3820008710.34185,2.00060534477234,22000.4296875,,,6,,,,36.9416033524933,,,1000,,,,,,,,,,,,,,,,,,,,,,1.99863624572754,2.00090932846069,22000.4296875,22000.4296875,,,2.32883358001709,,1,0,0,0,0.021209716796875,29.8142719268799,1,1,1,2.00039863586426,0,2.00000240547316,,,0.145287630186166,0.0041947219353401,0.146773264584931,0.0041966203735854,0.858926117420196,0.974305748939514,36.4190635681152,1.21917000797112e-05,30,4,200,0.0002586171322036,-0.604470670223236,0.099265955388546,3,,,,,,,,,,,,,,,,
,3820008797.594,2.00090539455414,24000.05078125,,,6,,,,36.9416033524933,,,1000,,,,,,,,,,,,,,,,,,,,,,1.99859738349915,2.0013062953949,24000.05078125,24000.05078125,,,2.33005928993225,,1,0,0,0,0.0206756591796875,29.8142719268799,1,1,1,2.00050449371338,0,2.00001201806245,,,0.147222961174615,0.0042506024891287,0.148728512127508,0.0042525238383223,0.858919203281403,0.974322080612183,36.4190292358398,,30,4,200,0.0002587863709777,-0.612658023834228,0.100764237344265,3,,,,,,,,,,,,,,,,
,3820008884.04012,2.0009024143219,26000.28125,,,6,,,,36.9416033524933,,,1000,,,,,,,,,,,,,,,,,,,,,,1.99873864650726,2.00114989280701,26000.28125,26000.28125,,,2.33099412918091,,1,0,0,0,0.0228118896484375,29.3255138397217,1,1,1,2.00114989280701,0,2.00002209787016,,,0.148773836008751,0.0042953707093583,0.150296185932571,0.004297345944035,0.858932554721832,0.974335312843323,36.4190635681152,0.0,30,4,200,0.0002597289858385,-0.618901073932648,0.101877592504025,3,,,,,,,,,,,,,,,,
,3820008972.32285,2.00060200691223,28000.47265625,,,6,,,,36.9416033524933,,,1000,,,,,,,,,,,,,,,,,,,,,,1.99879932403564,2.00096344947815,28000.47265625,28000.47265625,,,2.33103036880493,,1,0,0,0,0.0222015380859375,29.8142719268799,1,1,1,2.00043535232544,0,1.99997915603496,,,0.150039633444552,0.0043318788689959,0.151573239980719,0.0043338556727425,0.858991622924805,0.974367380142212,36.4192771911621,0.0,30,4,200,0.0001892563595902,-0.624396741390228,0.101777352392674,3,,,,,,,,,,,,,,,,
,3820009059.18711,2.00075924396515,30000.4140625,,,6,,,,36.9416033524933,,,1000,,,,,,,,,,,,,,,,,,,,,,1.99837267398834,2.000972032547,30000.4140625,30000.4140625,,,2.33125710487366,,1,0,0,0,0.023651123046875,29.8142719268799,1,1,1,2.00060248374939,0,2.00004198816088,,,0.151081157924367,0.0043619457561491,0.15262470537059,0.0043639219073442,0.85899955034256,0.974360287189484,36.4193115234375,0.0,30,4,200,0.0002525926684029,-0.628511369228363,0.103532902896404,3,,,,,,,,,,,,,,,,
,3820009147.64979,2.00061655044556,32000.314453125,,,6,,,,36.9416033524933,,,1000,,,,,,,,,,,,,,,,,,,,,,1.99867558479309,2.00110340118408,32000.314453125,32000.314453125,,,2.33234047889709,,1,0,0,0,0.0234222412109375,29.8142719268799,1,1,1,2.00012969970703,0,2.00004115274974,,,0.151949915758655,0.0043870032762058,0.153502087240828,0.0043890106181386,0.859042286872864,0.974359810352325,36.4194679260254,0.0,30,4,200,0.0002727353130467,-0.631768107414246,0.103947848081589,3,,,,,,,,,,,,,,,,
,3820009235.54684,2.00057685375214,34000.26171875,,,6,,,,36.9416033524933,,,1000,,,,,,,,,,,,,,,,,,,,,,1.99836492538452,2.00110530853271,34000.26171875,34000.26171875,,,2.33228349685669,,1,0,0,0,0.0229644775390625,29.8142719268799,1,1,1,2.00022506713867,0,1.9999606183597,,,0.152682215128025,0.004408089610341,0.154239438305028,0.0044100890080181,0.859124600887299,0.97436261177063,36.419807434082,6.03488254547119,30,4,200,0.000267121795332,-0.635139167308807,0.104549266397953,3,,,,,,,,,,,,,,,,
,3820009323.63812,2.00045335292816,36000.41796875,,,6,,,,36.9416033524933,,,1000,,,,,,,,,,,,,,,,,,,,,,1.99886000156403,2.00102996826172,36000.41796875,36000.41796875,,,2.33324694633484,,1,0,0,0,0.0215911865234375,29.3255138397217,1,1,1,2.0000159740448,0,2.00001587186541,,,0.153311920778267,0.0044262065141728,0.154873454881793,0.0044282174179965,0.859226584434509,0.974373340606689,36.4201545715332,1.20641652756603e-05,30,4,200,0.0002631512470543,-0.637694418430328,0.104560740292072,3,,,,,,,,,,,,,,,,
,3820009411.88194,2.00090348720551,38000.1953125,,,6,,,,36.9416033524933,,,1000,,,,,,,,,,,,,,,,,,,,,,1.99855625629425,2.00125169754028,38000.1953125,38000.1953125,,,2.33429718017578,,1,0,0,0,0.0212860107421875,29.8142719268799,1,1,1,2.00055527687073,0,2.00010151333279,,,0.153856249857494,0.0044418517805072,0.155420118189516,0.0044438476090965,0.859333992004394,0.974364101886749,36.4205894470215,0.109258837997913,30,4,200,0.0002704739163164,-0.639924764633179,0.104924194514751,3,,,,,,,,,,,,,,,,
,3820009500.51934,2.00108873844147,40000.29296875,,,6,,,,36.9416033524933,,,1000,,,,,,,,,,,,,,,,,,,,,,1.99877226352692,2.00115275382996,40000.29296875,40000.29296875,,,2.33472299575806,,1,0,0,0,0.02197265625,30.3030319213867,1,1,1,2.00110459327698,0,2.00004195315497,,,0.154331245071141,0.0044554882003892,0.155897221459471,0.0044574916305237,0.859458804130554,0.974368810653687,36.4210586547852,6.03498649597168,30,4,200,0.0002696693700272,-0.641606569290161,0.105444438755512,3,,,,,,,,,,,,,,,,
,3820009589.20456,2.00076711177826,42000.0859375,,,6,,,,36.9416033524933,,,1000,,,,,,,,,,,,,,,,,,,,,,1.99835193157196,2.00107765197754,42000.0859375,42000.0859375,,,2.33524084091187,,1,0,0,0,0.0238037109375,29.8142719268799,1,1,1,2.00059676170349,0,2.00003754209589,,,0.154750910559027,0.004467511319524,0.156317685667412,0.0044695114567596,0.859598755836487,0.974363803863525,36.4215927124023,0.0,30,4,200,0.0002612441312521,-0.643432676792145,0.105928666889668,3,,,,,,,,,,,,,,,,
,3820009676.64134,2.00101673603058,44000.23046875,,,6,,,,36.9416033524933,,,1000,,,,,,,,,,,,,,,,,,,,,,1.99854671955109,2.00131392478943,44000.23046875,44000.23046875,,,2.33609008789062,,1,0,0,0,0.0231170654296875,29.8142719268799,1,1,1,2.00071954727173,0,2.00000258002962,,,0.15512579545126,0.0044782013003678,0.156693358456644,0.004480251086461,0.859805464744568,0.974378526210785,36.4223823547363,0.0,30,4,200,0.0001584513083798,-0.645028531551361,0.105940960347652,3,,,,,,,,,,,,,,,,
,3820009764.08769,2.00063133239746,46000.25,,,6,,,,36.9416033524933,,,1000,,,,,,,,,,,,,,,,,,,,,,1.99852705001831,2.00117516517639,46000.25,46000.25,,,2.33521294593811,,1,0,0,0,0.0231170654296875,29.8142719268799,1,1,1,2.00008749961853,0,2.00005204589279,,,0.155457251546181,0.0044876992601327,0.157024281465395,0.0044897184217841,0.859919548034668,0.974354028701782,36.4228591918945,0.0,30,4,200,0.0002421068784315,-0.645830154418945,0.106338255107403,3,,,,,,,,,,,,,,,,
,3820009851.89098,2.00095999240875,48000.2109375,,,6,,,,36.9416033524933,,,1000,,,,,,,,,,,,,,,,,,,,,,1.99856209754944,2.00141286849976,48000.2109375,48000.2109375,,,2.33627414703369,,1,0,0,0,0.0238800048828125,29.8142719268799,1,1,1,2.00050711631775,0,2.00009849336412,,,0.155761170556453,0.0044963636682216,0.15732651294599,0.0044983595948251,0.860087752342224,0.974348247051239,36.4235000610352,0.0,30,4,200,0.000256579980487,-0.647148251533508,0.106484949588776,3,,,,,,,,,,,,,,,,
,3820009939.2248,2.00089800357819,49999.69921875,,,6,,,,36.9416033524933,,,1000,,,,,,,,,,,,,,,,,,,,,,1.99875998497009,2.00131916999817,49999.69921875,49999.69921875,,,2.337327003479,,1,0,0,0,0.0218963623046875,29.8142719268799,1,1,1,2.0004768371582,0,2.00001640830721,,,0.156035465748642,0.0045041662511246,0.157600291354652,0.004506187585823,0.860266745090485,0.974343836307526,36.4241828918457,0.0,30,4,200,0.0002532585058361,-0.64832204580307,0.106533125042915,3,,,,,,,,,,,,,,,,
,3820010025.95761,2.00065040588379,51999.76171875,,,6,,,,36.9416033524933,,,1000,,,,,,,,,,,,,,,,,,,,,,1.99840641021729,2.00091505050659,51999.76171875,51999.76171875,,,2.3381495475769,,1,0,0,0,0.0237274169921875,29.8142719268799,1,1,1,2.00061011314392,0,1.99997825805958,,,0.156289216955749,0.0045113558610482,0.15785080841926,0.0045133522279597,0.860478758811951,0.974336981773377,36.4250144958496,0.0,30,4,200,0.0002534952946007,-0.649426639080048,0.106524832546711,3,,,,,,,,,,,,,,,,
,3820010112.25928,2.00066649913788,54000.203125,,,6,,,,36.9416033524933,,,1000,,,,,,,,,,,,,,,,,,,,,,1.99851560592651,2.00093817710876,54000.203125,54000.203125,,,2.3386390209198,,1,0,0,0,0.0237274169921875,30.3030319213867,1,1,1,2.00053691864014,0,2.00003554644408,,,0.156523371202882,0.0045179851875377,0.158082101118442,0.0045199653352968,0.860679030418396,0.974329888820648,36.4257659912109,0.0,30,4,200,0.0002519546251278,-0.650469422340393,0.106570445001125,3,,,,,,,,,,,,,,,,
,3820010199.30518,2.00078403949738,55999.6953125,,,6,,,,36.9416033524933,,,1000,,,,,,,,,,,,,,,,,,,,,,1.99838721752167,2.00103402137756,55999.6953125,55999.6953125,,,2.33894038200378,,1,0,0,0,0.0012969970703125,29.3255138397217,1,1,1,2.00053405761719,0,1.99999998722758,,,0.156737142648623,0.0045240223245194,0.158293593575602,0.004526014351074,0.860888957977295,0.97432667016983,36.4266166687012,0.0,30,4,200,0.0002529019548092,-0.651532888412476,0.106449119746685,3,,,,,,,,,,,,,,,,
,3820010286.36589,2.00094020366669,57999.79296875,,,6,,,,36.9416033524933,,,1000,,,,,,,,,,,,,,,,,,,,,,1.99867844581604,2.00130867958069,57999.79296875,57999.79296875,,,2.34024548530579,,1,0,0,0,0.0217437744140625,29.8142719268799,1,1,1,2.00057172775269,0,2.00006351300648,,,0.156944853776738,0.0045298288300682,0.158496916262081,0.0045318259828006,0.861185431480408,0.974355399608612,36.427734375,6.03553915023804,30,4,200,0.0001036295725498,-0.653075277805328,0.107025444507599,3,,,,,,,,,,,,,,,,
,3820010373.4656,2.0009069442749,59999.75,,,6,,,,36.9416033524933,,,1000,,,,,,,,,,,,,,,,,,,,,,1.99867010116577,2.00130939483643,59999.75,59999.75,,,2.34146237373352,,1,0,0,0,0.0194549560546875,29.8142719268799,1,1,1,2.00050449371338,0,2.0001040785401,,,0.157131471797493,0.0045351127003552,0.158679734542111,0.0045370574210738,0.861343264579773,0.97430944442749,36.428352355957,0.139987379312515,30,4,200,0.0002912014024332,-0.652949213981628,0.107442662119865,3,,,,,,,,,,,,,,,,
,3820010459.64526,2.00072813034058,61999.55859375,,,6,,,,36.9416033524933,,,1000,,,,,,,,,,,,,,,,,,,,,,1.99859535694122,2.00091123580933,61999.55859375,61999.55859375,,,2.34002566337585,,1,0,0,0,0.0229644775390625,29.8142719268799,1,1,1,2.00067925453186,0,2.00004419132515,,,0.157307339907449,0.0045400287842127,0.158853550574444,0.0045420250529513,0.861588954925537,0.974309206008911,36.4293479919434,1.15170196295367e-05,30,4,200,0.0002366820845054,-0.653295814990997,0.10638914257288,3,,,,,,,,,,,,,,,,
,3820010546.34446,2.00066125392914,63999.63671875,,,6,,,,36.9416033524933,,,1000,,,,,,,,,,,,,,,,,,,,,,1.99867939949036,2.00108098983765,63999.63671875,63999.63671875,,,2.34157419204712,,1,0,0,0,0.0237274169921875,29.8142719268799,1,1,1,2.00084686279297,0,2.00004850540842,,,0.157478296060836,0.0045447817118529,0.159018582817635,0.0045467433228707,0.861870408058167,0.97430682182312,36.4304084777832,0.109220199286938,30,4,200,0.0002348678244743,-0.653827786445618,0.106607124209404,3,,,,,,,,,,,,,,,,
,3820010633.46321,2.00083065032959,65999.6875,,,6,,,,36.9416033524933,,,1000,,,,,,,,,,,,,,,,,,,,,,1.99819111824036,2.00114774703979,65999.6875,65999.6875,,,2.33971214294434,,1,0,0,0,0.0232696533203125,30.3030319213867,1,1,1,2.00073528289795,0,2.00009517757981,,,0.157645073824414,0.0045493710025558,0.159178797289411,0.0045513221849396,0.862224161624908,0.974345505237579,36.4317169189453,0.0001037899346556,30,4,200,3.06940492009744e-05,-0.656448602676392,0.107399493455887,3,,,,,,,,,,,,,,,,
,3820010720.71216,2.00061857700348,67999.484375,,,6,,,,36.9416033524933,,,1000,,,,,,,,,,,,,,,,,,,,,,1.99878203868866,2.00099468231201,67999.484375,67999.484375,,,2.34147667884827,,1,0,0,0,0.01953125,30.3030319213867,1,1,1,2.00060486793518,0,2.00000183229093,,,0.15779848493562,0.0045536226250789,0.159327625639292,0.0045555757202306,0.862495005130768,0.974339604377747,36.432788848877,0.109209775924683,30,4,200,2.60102824540809e-05,-0.656738042831421,0.106896221637726,3,,,,,,,,,,,,,,,,
,3820010809.2496,2.00109207630157,69999.546875,,,6,,,,36.9416033524933,,,1000,,,,,,,,,,,,,,,,,,,,,,1.99873638153076,2.00120949745178,69999.546875,69999.546875,,,2.34229731559753,,1,0,0,0,0.0179290771484375,29.8142719268799,1,1,1,2.00097465515137,0,2.00003147125244,,,0.157946625579819,0.004557698582732,0.159469606748101,0.0045596356769435,0.8628089427948,0.974348068237305,36.433967590332,0.0604317262768745,30,4,200,-1.47962873597862e-05,-0.656992077827454,0.107039116322994,3,,,,,,,,,,,,,,,,
,3820010896.38008,2.00077176094055,67999.6875,,,6,,,,36.9416033524933,,,1000,,,,,,,,,,,,,,,,,,,,,,1.9981392621994,2.00131726264954,67999.6875,67999.6875,,,2.34392857551575,,1,0,0,0,0.0228118896484375,29.8142719268799,1,1,1,2.00057744979858,0,2.00007974675723,,,0.157789400282763,0.004553522541757,0.159324439590941,0.0045554873126624,0.862243711948395,0.974330008029938,36.4318428039551,0.0,30,4,200,0.0001829455286497,-0.656094074249268,0.107676930725574,3,,,,,,,,,,,,,,,,
,3820010985.68276,2.0007141828537,65999.8046875,,,6,,,,36.9416033524933,,,1000,,,,,,,,,,,,,,,,,,,,,,1.99868905544281,2.00123357772827,65999.8046875,65999.8046875,,,2.3435435295105,,1,0,0,0,0.0196075439453125,29.8142719268799,1,1,1,2.00019478797913,0,2.00010219768242,,,0.157634256197885,0.0045493353006124,0.159178072819311,0.0045513013783936,0.861790478229523,0.974337458610535,36.4300575256348,0.0,30,4,200,0.000160518931807,-0.654813230037689,0.106729067862034,3,,,,,,,,,,,,,,,,
,3820011076.47834,2.00073277950287,63999.50390625,,,6,,,,36.9416033524933,,,1000,,,,,,,,,,,,,,,,,,,,,,1.99843108654022,2.0011420249939,63999.50390625,63999.50390625,,,2.3434624671936,,1,0,0,0,0.02197265625,31.7693061828613,1,1,1,2.00032353401184,0,1.99997754607882,,,0.157468264776384,0.0045448400988849,0.15902167313063,0.004546825231394,0.86132425069809,0.974341869354248,36.4282684326172,0.0,30,4,200,0.000210688856896,-0.654690146446228,0.106799699366093,3,,,,,,,,,,,,,,,,
,3820011167.00204,2.00083875656128,61999.8984375,,,6,,,,36.9416033524933,,,1000,,,,,,,,,,,,,,,,,,,,,,1.99806654453278,2.00119209289551,61999.8984375,61999.8984375,,,2.34337997436523,,1,0,0,0,0.0171661376953125,30.3030319213867,1,1,1,2.00085377693176,0,2.00001958564476,,,0.157300002475246,0.0045402149107508,0.158860520551572,0.0045422178491383,0.860966682434082,0.974350333213806,36.4268646240234,0.0,30,4,200,0.0001499748905189,-0.653808355331421,0.107053935527802,3,,,,,,,,,,,,,,,,
,3820011255.4046,2.00059652328491,59999.7734375,,,6,,,,36.9416033524933,,,1000,,,,,,,,,,,,,,,,,,,,,,1.99786972999573,2.00097894668579,59999.7734375,59999.7734375,,,2.34205341339111,,1,0,0,0,0.0237274169921875,30.3030319213867,1,1,1,2.00059652328491,0,1.99999898213607,,,0.157121043100874,0.0045352703844913,0.158687264039267,0.0045372628714186,0.860621750354767,0.974349498748779,36.4255256652832,1.17249473987613e-05,30,4,200,0.0001421299675712,-0.653578817844391,0.106749020516872,3,,,,,,,,,,,,,,,,
,3820011343.47696,2.00089871883392,57999.8671875,,,6,,,,36.9416033524933,,,1000,,,,,,,,,,,,,,,,,,,,,,1.99843084812164,2.00137853622437,57999.8671875,57999.8671875,,,2.34178733825684,,1,0,0,0,0.0208282470703125,29.8142719268799,1,1,1,2.00041890144348,0,2.00002812487738,,,0.156928579122698,0.004529946641616,0.158501425614834,0.0045319517111476,0.860269546508789,0.974368691444397,36.4241790771484,,30,4,200,0.0001461252832086,-0.652249872684479,0.1071982011199,3,,,,,,,,,,,,,,,,
,3820011432.45755,2.00087082386017,55999.64453125,,,6,,,,36.9416033524933,,,1000,,,,,,,,,,,,,,,,,,,,,,1.99840450286865,2.0011568069458,55999.64453125,55999.64453125,,,2.34377217292786,,1,0,0,0,0.0238800048828125,29.8142719268799,1,1,1,2.00058484077454,0,2.00002178549767,,,0.15672518240135,0.004524264747878,0.158303570366875,0.0045262939657218,0.859976708889008,0.974376916885376,36.4230308532715,9.15299701690674,30,4,200,0.0001387191296089,-0.652453064918518,0.10674837231636,3,,,,,,,,,,,,,,,,
,3820011521.39776,2.00083518028259,53999.6953125,,,6,,,,36.9416033524933,,,1000,,,,,,,,,,,,,,,,,,,,,,1.99886298179626,2.00102829933166,53999.6953125,53999.6953125,,,2.34090757369995,,1,0,0,0,0.0238800048828125,30.3030319213867,1,1,1,2.00065946578979,0,2.00003901124001,,,0.156509356674804,0.004518220485215,0.15809181615829,0.0045202390194991,0.859688401222229,0.974378883838654,36.421932220459,0.0,30,4,200,0.000139261392178,-0.651409447193146,0.106769762933254,3,,,,,,,,,,,,,,,,
,3820011610.56545,2.00084149837494,51999.76171875,,,6,,,,36.9416033524933,,,1000,,,,,,,,,,,,,,,,,,,,,,1.99876499176025,2.00132298469543,51999.76171875,51999.76171875,,,2.34247875213623,,1,0,0,0,0.01800537109375,30.3030319213867,1,1,1,2.00036001205444,0,2.00007300130252,,,0.156271469322054,0.0045115448011723,0.157859664841114,0.0045136012224809,0.859390914440155,0.974374532699585,36.4207916259766,0.0001100429508369,30,4,200,0.0001957241183845,-0.6501105427742,0.106678612530231,3,,,,,,,,,,,,,,,,
,3820011701.96791,2.00070941448212,49999.56640625,,,6,,,,36.9416033524933,,,1000,,,,,,,,,,,,,,,,,,,,,,1.99850916862488,2.00118827819824,49999.56640625,49999.56640625,,,2.34227514266968,,1,0,0,0,0.02288818359375,29.8142719268799,1,1,1,2.00031757354736,0,2.00008771154616,,,0.156025188561695,0.0045045357658095,0.157614658311505,0.0045065923492788,0.859232008457184,0.974390685558319,36.420166015625,0.0,30,4,200,0.0001056576147675,-0.649800419807434,0.106658019125462,3,,,,,,,,,,,,,,,,
,3820011790.93112,2.0009753704071,47999.60546875,,,6,,,,36.9416033524933,,,1000,,,,,,,,,,,,,,,,,,,,,,1.99846982955933,2.00119709968567,47999.60546875,47999.60546875,,,2.34224724769592,,1,0,0,0,0.0217437744140625,31.7693061828613,1,1,1,2.00075364112854,0,2.00005351219858,,,0.155748789818392,0.0044967098101371,0.157340737545097,0.0044987591035498,0.858993649482727,0.974398791790009,36.4192199707031,0.0001107817734009,30,4,200,0.0001079150097211,-0.648834824562073,0.106292136013508,3,,,,,,,,,,,,,,,,
,3820011879.76506,2.00073742866516,45999.66796875,,,6,,,,36.9416033524933,,,1000,,,,,,,,,,,,,,,,,,,,,,1.99809038639069,2.00106477737427,45999.66796875,45999.66796875,,,2.34173369407654,,1,0,0,0,0.0223541259765625,30.3030319213867,1,1,1,2.00074696540833,0,2.00001371332577,,,0.155440968974012,0.0044879990534961,0.157036299313771,0.004490055464941,0.858719646930695,0.974385142326355,36.4182205200195,0.0,30,4,200,0.0002256180014228,-0.646243155002594,0.105839177966118,3,,,,,,,,,,,,,,,,
,3820011968.37107,2.00072121620178,43999.5703125,,,6,,,,36.9416033524933,,,1000,,,,,,,,,,,,,,,,,,,,,,1.99846982955933,2.00096917152405,43999.5703125,43999.5703125,,,2.33978009223938,,1,0,0,0,0.0183868408203125,30.3030319213867,1,1,1,2.00080847740173,0,1.99999909930759,,,0.155112303359237,0.0044785909483149,0.156706086621468,0.0044806150625459,0.858599245548248,0.974405944347382,36.4177131652832,0.0,30,4,200,0.0001271782384719,-0.645918250083923,0.10566196590662,3,,,,,,,,,,,,,,,,
,3820012058.14492,2.00082981586456,41999.71875,,,6,,,,36.9416033524933,,,1000,,,,,,,,,,,,,,,,,,,,,,1.99820828437805,2.0011351108551,41999.71875,41999.71875,,,2.340491771698,,1,0,0,0,0.023345947265625,30.3030319213867,1,1,1,2.00052452087402,0,1.9999739240717,,,0.154739504871172,0.0044679259137965,0.156334574336771,0.0044699897874468,0.858440935611725,0.974402010440826,36.4171257019043,,30,4,200,0.0001187288580695,-0.644563376903534,0.105813018977642,3,,,,,,,,,,,,,,,,
,3820012146.36617,2.00074684619904,39999.68359375,,,6,,,,36.9416033524933,,,1000,,,,,,,,,,,,,,,,,,,,,,1.99866425991058,2.00084853172302,39999.68359375,39999.68359375,,,2.34037780761719,,1,0,0,0,0.0234222412109375,30.3030319213867,1,1,1,2.00064516067505,0,2.0000165215245,,,0.154321417297655,0.0044559557393013,0.15591510278191,0.0044579961553294,0.858284652233124,0.974409997463226,36.4165000915527,1.22741712402785e-05,30,4,200,0.0001178803577204,-0.642898678779602,0.105553023517132,3,,,,,,,,,,,,,,,,
,3820012234.37477,2.0010302066803,37999.63671875,,,6,,,,36.9416033524933,,,1000,,,,,,,,,,,,,,,,,,,,,,1.99818408489227,2.00107908248901,37999.63671875,37999.63671875,,,2.34005045890808,,1,0,0,0,0.018310546875,29.8142719268799,1,1,1,2.00098133087158,0,1.99997319998565,,,0.153848364152916,0.0044423594630655,0.155439473254299,0.0044443957177588,0.858185112476349,0.974409282207489,36.4161186218262,6.03457689285278,30,4,200,0.0001194024589494,-0.64005172252655,0.105165280401707,3,,,,,,,,,,,,,,,,
,3820012322.9062,2.0007529258728,35999.82421875,,,6,,,,36.9416033524933,,,1000,,,,,,,,,,,,,,,,,,,,,,1.99840223789215,2.00103569030762,35999.82421875,35999.82421875,,,2.33883833885193,,1,0,0,0,0.0237274169921875,29.8142719268799,1,1,1,2.00047016143799,0,2.00006950784613,,,0.153303532980598,0.0044267132970596,0.154892346592561,0.0044287546172731,0.858055830001831,0.974412500858307,36.4156227111816,0.109279207885265,30,4,200,0.0001123670954257,-0.638790786266327,0.104841835796833,3,,,,,,,,,,,,,,,,
,3820012411.38427,2.00067782402039,33999.875,,,6,,,,36.9416033524933,,,1000,,,,,,,,,,,,,,,,,,,,,,1.99834656715393,2.00105285644531,33999.875,33999.875,,,2.33957290649414,,1,0,0,0,0.0191497802734375,29.8142719268799,1,1,1,2.00061178207397,0,1.99998788921921,,,0.152675012045294,0.0044086192476034,0.154258923567793,0.004410642979707,0.857968986034393,0.974411010742188,36.4152870178223,0.0001130488089984,30,4,200,0.0001135314741986,-0.636130213737488,0.103897295892239,3,,,,,,,,,,,,,,,,
,3820012500.46541,2.00103950500488,31999.8359375,,,6,,,,36.9416033524933,,,1000,,,,,,,,,,,,,,,,,,,,,,1.99862921237946,2.00129818916321,31999.8359375,31999.8359375,,,2.33936977386475,,1,0,0,0,0.01953125,29.8142719268799,1,1,1,2.00078082084656,0,2.00001130280671,,,0.151944559068922,0.0043875586780575,0.153522888736866,0.0043895954819765,0.857917785644531,0.974426448345184,36.4150848388672,0.0,30,4,200,8.84888504515402e-05,-0.633978724479675,0.103586137294769,3,,,,,,,,,,,,,,,,
,3820012587.80239,2.00052177906036,30000.154296875,,,6,,,,36.9416033524933,,,1000,,,,,,,,,,,,,,,,,,,,,,1.99842154979706,2.0011739730835,30000.154296875,30000.154296875,,,2.33919286727905,,1,0,0,0,0.0238800048828125,29.8142719268799,1,1,1,2.00015234947205,0,2.00001137171473,,,0.15106426873717,0.0043622320878984,0.15263730541136,0.0043642766534617,0.857767581939697,0.974385976791382,36.4145202636719,0.141955703496933,30,4,200,0.000235213432461,-0.628322958946228,0.103402860462666,3,,,,,,,,,,,,,,,,
,3820012678.53539,2.00047266483307,27999.70703125,,,6,,,,36.9416033524933,,,1000,,,,,,,,,,,,,,,,,,,,,,1.9983811378479,2.00074791908264,27999.70703125,27999.70703125,,,2.33889651298523,,1,0,0,0,0.01678466796875,30.7917900085449,1,1,1,2.0002429485321,0,1.99998176539386,,,0.150024339281031,0.0043321921368541,0.151584917355461,0.0043341895613209,0.857789576053619,0.974388778209686,36.4145736694336,,30,4,200,0.0001542314857942,-0.62425297498703,0.102674923837185,3,,,,,,,,,,,,,,,,
,3820012765.28803,2.00094437599182,26000.07421875,,,6,,,,36.9416033524933,,,1000,,,,,,,,,,,,,,,,,,,,,,1.99832880496979,2.00121235847473,26000.07421875,26000.07421875,,,2.34006595611572,,1,0,0,0,0.021820068359375,29.8142719268799,1,1,1,2.00092339515686,0,2.0000645937743,,,0.14876048854735,0.0042957080790182,0.150308598737902,0.0042976955825886,0.857767641544342,0.974378108978271,36.4145469665527,0.0,30,4,200,0.0001490972790634,-0.618947207927704,0.101732365787029,3,,,,,,,,,,,,,,,,
,3820012854.965,2.00049030780792,24000.357421875,,,6,,,,36.9416033524933,,,1000,,,,,,,,,,,,,,,,,,,,,,1.99875235557556,2.00087189674377,24000.357421875,24000.357421875,,,2.33902955055237,,1,0,0,0,0.02166748046875,30.3030319213867,1,1,1,2.00073027610779,0,2.00002261570522,,,0.147206058577787,0.0042508242740854,0.148738691744646,0.0042528106672809,0.857763648033142,0.97435861825943,36.4145736694336,0.0,30,4,200,0.0001475030294386,-0.613023817539215,0.100543558597565,3,,,,,,,,,,,,,,,,
,3820012944.7663,2.00037348270416,22000.4921875,,,6,,,,36.9416033524933,,,1000,,,,,,,,,,,,,,,,,,,,,,1.99868810176849,2.00104141235352,22000.4921875,22000.4921875,,,2.33828687667847,,1,0,0,0,0.0228118896484375,28.8367557525635,1,1,1,1.99987864494324,0,2.00002827026226,,,0.145270102185746,0.0041948962094459,0.14678074115417,0.004196831775584,0.857806086540222,0.97434002161026,36.4147262573242,0.0,30,4,200,0.0001463516964577,-0.605060040950775,0.0994223803281784,3,,,,,,,,,,,,,,,,
,3820013032.96705,2.00092053413391,20000.298828125,,,6,,,,36.9416033524933,,,1000,,,,,,,,,,,,,,,,,,,,,,1.99870908260345,2.00112771987915,20000.298828125,20000.298828125,,,2.33770871162415,,1,0,0,0,0.02288818359375,29.8142719268799,1,1,1,2.00071334838867,0,2.00001730663436,,,0.142817182873429,0.0041240279342771,0.144301684582212,0.0041259487431405,0.857861936092377,0.974316418170929,36.4149513244629,0.0,30,4,200,0.0001339018490398,-0.594891667366028,0.0976652503013611,3,,,,,,,,,,,,,,,,
,3820013124.42562,2.00099265575409,18000.421875,,,6,,,,36.9416033524933,,,1000,,,,,,,,,,,,,,,,,,,,,,1.99848258495331,2.0011191368103,18000.421875,18000.421875,,,2.33783388137817,,1,0,0,0,0.0152587890625,30.3030319213867,1,1,1,2.00096869468689,0,2.00000195418085,,,0.139652990253003,0.0040326368217206,0.141103783208852,0.0040345189417606,0.857903063297272,0.974285125732422,36.4151344299316,1.24948355733068e-05,30,4,200,0.0001331057137576,-0.582112491130829,0.0955747961997986,3,,,,,,,,,,,,,,,,
,3820013213.58611,2.00089538097382,16000.423828125,,,6,,,,36.9416033524933,,,1000,,,,,,,,,,,,,,,,,,,,,,1.9987485408783,2.00119733810425,16000.423828125,16000.423828125,,,2.33667731285095,,1,0,0,0,0.022125244140625,30.3030319213867,1,1,1,2.00059342384338,0,2.00001331738063,,,0.135499196064498,0.003912648977172,0.136904377598435,0.0039144472216906,0.857971489429474,0.974249243736267,36.4154357910156,6.03452014923096,30,4,200,0.0001259536220459,-0.564280688762665,0.0926550030708313,3,,,,,,,,,,,,,,,,
,3820013302.59586,2.00046336650848,14000.23046875,,,6,,,,36.9416033524933,,,1000,,,,,,,,,,,,,,,,,,,,,,1.99867022037506,2.00093698501587,14000.23046875,14000.23046875,,,2.33874225616455,,1,0,0,0,0.02349853515625,29.8142719268799,1,1,1,2.00013828277588,0,2.00000759107726,,,0.129982245244518,0.0037533308898722,0.13132918728395,0.0037550446629095,0.857994735240936,0.974193036556244,36.4155654907227,0.0,30,4,200,0.0001521663361927,-0.541491746902466,0.0888699069619179,3,,,,,,,,,,,,,,,,
,3820013391.75708,2.00086438655853,12000.2578125,,,6,,,,36.9416033524933,,,1000,,,,,,,,,,,,,,,,,,,,,,1.99860095977783,2.00093007087708,12000.2578125,12000.2578125,,,2.3392391204834,,1,0,0,0,0.0229644775390625,30.7917900085449,1,1,1,2.00079870223999,0,2.00000909081212,,,0.122572681217328,0.0035393680890317,0.123843915401597,0.0035410264127157,0.85800713300705,0.974136650562286,36.4156608581543,,30,4,200,0.0001843710342654,-0.509906589984894,0.0840573906898499,3,,,,,,,,,,,,,,,,
,3820013480.02802,2.00064122676849,10000.271484375,,,6,,,,36.9416033524933,,,1000,,,,,,,,,,,,,,,,,,,,,,1.9987006187439,2.00094151496887,10000.271484375,10000.271484375,,,2.33858847618103,,1,0,0,0,0.0209808349609375,29.8142719268799,1,1,1,2.00074434280396,0,2.00001164277395,,,0.112559438555187,0.0032502261032855,0.113725427385336,0.003251721462571,0.858019292354584,0.97405731678009,36.4157981872559,0.0,30,4,200,0.0001768711372278,-0.469340085983276,0.0762114822864532,3,,,,,,,,,,,,,,,,
,3820013569.12702,2.0005110502243,8000.2607421875,,,6,,,,36.9416033524933,,,1000,,,,,,,,,,,,,,,,,,,,,,1.99881017208099,2.00104808807373,8000.2607421875,8000.2607421875,,,2.34062623977661,,1,0,0,0,0.0235748291015625,29.8142719268799,1,1,1,2.00046706199646,0,2.00000495822341,,,0.0990619095794705,0.0028604902546816,0.100088944334156,0.0028618219439713,0.857978880405426,0.973954439163208,36.4156951904297,9.15050220489502,30,4,200,0.0001944642863236,-0.412680864334106,0.0668620243668556,3,,,,,,,,,,,,,,,,
,3820013658.77976,2.00092160701752,6000.35986328125,,,6,,,,36.9416033524933,,,1000,,,,,,,,,,,,,,,,,,,,,,1.99882340431213,2.00096988677979,6000.35986328125,6000.35986328125,,,2.34017467498779,,1,0,0,0,0.0235748291015625,30.3030319213867,1,1,1,2.00099682807922,0,2.00000556877681,,,0.0812343870877872,0.0023456402891224,0.0820737977407689,0.0023467193233727,0.858175039291382,0.973949611186981,36.4164505004883,0.280828267335892,30,4,200,1.01078039733693e-05,-0.341110378503799,0.0553307086229324,3,,,,,,,,,,,,,,,,
,3820013747.00899,2.00106656551361,4000.31298828125,,,6,,,,36.9416033524933,,,1000,,,,,,,,,,,,,,,,,,,,,,1.99859249591827,2.00124168395996,4000.31298828125,4000.31298828125,,,2.34206795692444,,1,0,0,0,0.0,29.8142719268799,1,1,1,2.00089144706726,0,2.00005773261741,,,0.0596172743265039,0.0017217203166382,0.0602363258870652,0.0017225271307064,0.857081413269043,0.969778418540955,36.4153747558594,0.109291203320026,30,4,200,-5.7416305935476e-05,-0.25636699795723,0.0409152209758759,3,,,,,,,,,,,,,,,,
,3820013836.45591,2.00053703784943,2000.44873046875,,,6,,,,36.9416033524933,,,1000,,,,,,,,,,,,,,,,,,,,,,1.99863350391388,2.00087833404541,2000.44873046875,2000.44873046875,,,2.3414454460144,,1,0,0,0,0.0225830078125,30.3030319213867,1,1,1,2.00029182434082,0,2.0000158018536,,,0.0436764455952694,0.0012616075604883,0.0441304975857609,0.0012621976294617,0.855722308158874,0.964141249656677,36.4150772094727,0.0,30,4,200,-8.01218484411947e-05,-0.189272552728653,0.0294810235500336,3,,,,,,,,,,,,,,,,
,3820013930.17038,2.00079500675201,0.304482311010361,,,6,,,,36.9416033524933,,,1,,,,,,,,,,,,,,,,,,,,,,1.99862813949585,2.00095224380493,0.304482311010361,0.304482311010361,,,2.34256839752197,,1,0,0,0,0.02288818359375,31.2805480957031,1,1,1,2.0006377696991,0,2.00002180205451,,,-0.0004825909385233,1.51467504844196e-05,-0.0004865833200505,1.515245264856e-05,0.586902558803558,0.603130877017975,36.4713134765625,0.0,30,4,200,-0.0324189253151417,-0.889617204666138,3.05032444000244,3,,,,,,,,,,,,,,,,